Workbook

Sheet Dashboard
A1: NivrāaCare — Dynamic Unit Economics Dashboard | CFO View | J1: Service Selector Source | K1: Hour Options
A2: Select service + hours. Case 1 = patient arranges transport. Case 2 = NivrāaCare coordinates a third-party cab. Contribution is before fixed costs. | J2: Hospital Visit | K2: 1
J3: Hospital Visit — Concierge at Hospital | K3: 1.5
A4: Selected Service | B4: Hospital Visit | C4: Selected Hours | D4: 5 | J4: Clinic Visit | K4: 2
E5: Model | F5: Contribution Before Fixed Costs | J5: Diagnostic Center Visit | K5: 2.5
A6: Metric | B6: Case 1 — Patient Transport | C6: Case 2 — NivrāaCare 3P Cab | E6: Case 1 | F6: =B16 -> 1319.8032 | J6: Health Check-up Concierge | K6: 3
A7: Service Hours | B7: =$D$4 -> 5 | C7: =$D$4 -> 5 | E7: Case 2 | F7: =C16 -> 1458.8032 | J7: Hospital Admission Concierge | K7: 3.5
A8: Service Pricing Multiplier | B8: =SUMIF('Service Economics'!$A$5:$A$34,$B$4,'Service Economics'!$D$5:$D$34) -> 1 | C8: =B8 -> 1 | E8: Uplift | F8: =C19 -> 139 | J8: Hospital Discharge Concierge | K8: 4
A9: Customer Care Price (incl. GST) | B9: ='MVP1 Pricing & SKU'!$B$9+MAX($D$4,'MVP1 Pricing & SKU'!$B$5)*'MVP1 Pricing & SKU'!$B$7*$B$8+SUMIF('Service Economics'!$A$5:$A$34,$B$4,'Service Economics'!$E$5:$E$34) -> 1694 | C9: =B9 -> 1694 | J9: Overnight Hospital Concierge | K9: 4.5
A10: Net Care Revenue | B10: =B9/(1+'Global Inputs'!$B$7) -> 1435.5932 | C10: =B10 -> 1435.5932 | J10: Multi-Day Hospital Concierge (per 12h shift) | K10: 5
A11: Transport Customer Collection | B11: 0 | C11: =IF(SUMIF('Service Economics'!$A$5:$A$34,$B$4,'Service Economics'!$H$5:$H$34)=0,'Global Inputs'!$B$15,SUMIF('Service Economics'!$A$5:$A$34,$B$4,'Service Economics'!$H$5:$H$34))+IF(SUMIF('Service Economics'!$A$5:$A$34,$B$4,'Service Economics'!$I$5:$I$34)=0,'Global Inputs'!$B$16,SUMIF('Service Economics'!$A$5:$A$34,$B$4,'Service Economics'!$I$5:$I$34)) -> 649 | J11: Day Surgery / Procedure Concierge | K11: 5.5
A12: Pass-through Cab Amount | B12: 0 | C12: =IF(SUMIF('Service Economics'!$A$5:$A$34,$B$4,'Service Economics'!$H$5:$H$34)=0,'Global Inputs'!$B$15,SUMIF('Service Economics'!$A$5:$A$34,$B$4,'Service Economics'!$H$5:$H$34)) -> 500 | J12: Pre-Surgery Concierge | K12: 6
A13: Total Customer Outflow | B13: =B9+B11 -> 1694 | C13: =C9+C11 -> 2343 | J13: Post-Surgery Follow-up | K13: 6.5
A14: Net Operating Revenue | B14: =B10 -> 1435.5932 | C14: =C10+IF(SUMIF('Service Economics'!$A$5:$A$34,$B$4,'Service Economics'!$I$5:$I$34)=0,'Global Inputs'!$B$16,SUMIF('Service Economics'!$A$5:$A$34,$B$4,'Service Economics'!$I$5:$I$34))/(1+'Global Inputs'!$B$17) -> 1584.5932 | J14: Dialysis Visit Concierge | K14: 7
A15: Variable Delivery Cost | B15: =($D$4*SUMIF('Service Economics'!$A$5:$A$34,$B$4,'Service Economics'!$F$5:$F$34)*IF(SUMIF('Service Economics'!$A$5:$A$34,$B$4,'Service Economics'!$G$5:$G$34)=0,'Global Inputs'!$B$6,SUMIF('Service Economics'!$A$5:$A$34,$B$4,'Service Economics'!$G$5:$G$34)))+(B9*'Global Inputs'!$B$8+'Global Inputs'!$B$9)+SUM('Global Inputs'!$B$10:$B$14)+((B9/(1+'Global Inputs'!$B$7))*'NC Credits'!$B$15) -> 115.79 | C15: =B15+C11*'Global Inputs'!$B$8+'Global Inputs'!$B$18 -> 125.79 | J15: Chemotherapy Visit Concierge | K15: 7.5
A16: Contribution Before Fixed Costs | B16: =B14-B15 -> 1319.8032 | C16: =C14-C15 -> 1458.8032 | J16: Radiation Therapy Concierge | K16: 8
A17: Contribution Margin | B17: =IF(B14=0,0,B16/B14) -> 0.91934345 | C17: =IF(C14=0,0,C16/C14) -> 0.92061685 | J17: Physiotherapy / Rehab Visit | K17: 8.5
A18: Contribution / Service Hour | B18: =IF($D$4=0,0,B16/$D$4) -> 263.96064 | C18: =IF($D$4=0,0,C16/$D$4) -> 291.76064 | J18: Chronic Care Follow-up | K18: 9
A19: Contribution Uplift vs Case 1 | B19: 0 | C19: =C16-B16 -> 139 | J19: NRI Parent Medical Concierge | K19: 9.5
J20: Second Opinion Concierge | K20: 10
A21: Selected Hours is a dashboard-only scenario override. Minimum billing remains 2 hours. Service multipliers reflect effort/value and remain editable in Service Economics. | J21: Teleconsultation Concierge | K21: 10.5
J22: Medical Records Concierge | K22: 11
J23: Insurance / TPA Desk Concierge | K23: 11.5
A24: Selected Journey — Detailed CFO Breakup | J24: Hospital Transfer Concierge | K24: 12
A25: ="Live calculation for "&$B$4&" | "&TEXT($D$4,"0.0")&" hours | Pricing, loyalty, transport and Angel economics" -> Live calculation for Hospital Visit | 5.0 hours | Pricing, loyalty, transport and Angel economics | J25: Rehab / Nursing Facility Transfer | K25: 12.5
A26: Metric | B26: Case 1 — Patient Transport | C26: Case 2 — NivrāaCare 3P Cab | D26: CFO Formula / Meaning | F26: CFO Lens — What the Journey Really Earns | J26: 24×7 Urgent Care Coordination | K26: 13
A27: Customer Care Price (incl. GST) | B27: =B9 -> 1694 | C27: =C9 -> 1694 | D27: See Customer Care Price Build-Up below for the complete tier-by-tier calculation. | F27: Current Angel Utilization | G27: ='Angel Economics'!$G$9 -> 0.18104625 | J27: Doctor-at-Home Coordination | K27: 13.5
A28: Less: Embedded GST | B28: =B27-B29 -> 258.40678 | C28: =C27-C29 -> 258.40678 | D28: Customer care price less net care revenue; reflects embedded GST. | F28: Target Angel Utilization | G28: ='Angel Economics'!$H$9 -> 0.65 | J28: Nurse-at-Home Coordination | K28: 14
A29: Net Care Revenue | B29: =B10 -> 1435.5932 | C29: =C10 -> 1435.5932 | D29: Care revenue after removing GST. | F29: Current Fully Loaded Angel Cost / Hr | G29: ='Angel Economics'!$G$10 -> 241.65096 | J29: Medical Tourism — Concierge Package (24 HR Basis) | K29: 14.5
A30: Transport Customer Collection | B30: =B11 -> 0 | C30: =C11 -> 649 | D30: Case 2 = cab reimbursement + transport coordination fee. | F30: Target Fully Loaded Angel Cost / Hr | G30: ='Angel Economics'!$H$10 -> 103.5503 | J30: Pharmacy / Prescription Coordination | K30: 15
A31: Less: Pass-through Cab Amount | B31: =B12 -> 0 | C31: =C12 -> 500 | D31: Cab reimbursement collected and paid onward; not operating revenue. | F31: Case 1 Incremental Contribution / Hr | G31: =B44/$D$4 -> 263.96064 | J31: Family Medical Update Concierge | K31: 15.5
A32: Transport Coordination Fee | B32: =MAX(0,B30-B31) -> 0 | C32: =MAX(0,C30-C31) -> 149 | D32: Transport collection less pass-through cab amount. | F32: Case 2 Incremental Contribution / Hr | G32: =C44/$D$4 -> 291.76064 | K32: 16
A33: Net Operating Revenue | B33: =B14 -> 1435.5932 | C33: =C14 -> 1584.5932 | D33: Net care revenue + net transport coordination revenue. | F33: Case 1 Fully Loaded Contribution — Current | G33: =B46 -> 111.54842 | K33: 16.5
A34: Payment Platform Cost | B34: =$B$27*'Global Inputs'!$B$8+'Global Inputs'!$B$9 -> 0 | C34: =$C$27*'Global Inputs'!$B$8+'Global Inputs'!$B$9+$C$30*'Global Inputs'!$B$8 -> 0 | D34: Care gateway fee + fixed gateway fee + transport gateway fee where applicable. | F34: Case 2 Fully Loaded Contribution — Current | G34: =C46 -> 250.54842 | K34: 17
A35: Ops / Support Allocation | B35: ='Global Inputs'!$B$10 -> 10 | C35: ='Global Inputs'!$B$10 -> 10 | D35: Per-journey operating/support variable allocation. | F35: Case 1 Fully Loaded Contribution — Target | G35: =B47 -> 802.05174 | K35: 17.5
A36: Insurance / Risk Reserve | B36: ='Global Inputs'!$B$11 -> 10 | C36: ='Global Inputs'!$B$11 -> 10 | D36: Per-journey insurance / risk reserve. | F36: Case 2 Fully Loaded Contribution — Target | G36: =C47 -> 941.05174 | K36: 18
A37: WhatsApp / SMS / Communication | B37: ='Global Inputs'!$B$12 -> 0.5 | C37: ='Global Inputs'!$B$12 -> 0.5 | D37: Per-journey messaging / communication cost. | F37: Case 2 Transport Uplift | G37: =C44-B44 -> 139 | K37: 18.5
A38: BGV + Training Allocation | B38: ='Global Inputs'!$B$13 -> 0 | C38: ='Global Inputs'!$B$13 -> 0 | D38: Per-journey BGV/training allocation. | F38: Current Density Status | G38: =IF(G27<40%,"RED — payroll density too low",IF(G27<60%,"AMBER — improve utilization","GREEN — healthy utilization")) -> RED — payroll density too low | K38: 19
A39: Refund / Service Recovery Reserve | B39: ='Global Inputs'!$B$14 -> 36 | C39: ='Global Inputs'!$B$14 -> 36 | D39: Expected refund / service recovery reserve. | K39: 19.5
A40: Expected NC Credits Cost | B40: =$B$29*'NC Credits'!$B$15 -> 59.29 | C40: =$C$29*'NC Credits'!$B$15 -> 59.29 | D40: Net care revenue × expected NC loyalty cost rate. | F40: CFO interpretation: Contribution Before Fixed Costs is the marginal journey economics. Fully Loaded Contribution additionally allocates salaried Angel payroll. When utilization is low, the same payroll is spread across too few productive hours, so a journey can look highly profitable incrementally while producing much less fully loaded contribution. | K40: 20
...

Sheet Global Inputs
A1: NivrāaCare — Global Unit Economics Inputs
A2: Change only blue numbers. Change any input and service profitability updates automatically. NC loyalty assumptions are controlled separately in the 'NC Credits' sheet.
A4: Input | B4: Value | C4: Unit | D4: Source / Note | F4: Governance
A5: Base customer charge per concierge hour | B5: ='MVP1 Pricing & SKU'!$B$7 -> 299 | C5: ₹ / hour | D5: Linked to Global Pricing Config — active master base hourly rate | F5: Founder Assumption
A6: Angel cost per hour | B6: 0 | C6: ₹ / Angel hour | D6: Founder working assumption: ₹700 ÷ 4 hours | E6: When we are keeping 3 Angels on payroll, then we do not have to pay them on per hour basis, so I have made per hour cost as ZERO.Angel payment 14K Per month | F6: Founder Assumption
A7: GST on care service | B7: ='Global Pricing Config'!$B$8 -> 0.18 | C7: % | D7: Illustrative assumption; confirm with CA | F7: Market Test / CA Confirmation
A8: Payment platform fee | B8: 0 | C8: % of customer collection | D8: Editable payment gateway assumption | F8: Market Test
A9: Payment platform fixed fee | B9: 0 | C9: ₹ / transaction | D9: Editable | F9: Founder Assumption
A10: Ops / support allocation | B10: 10 | C10: ₹ / journey | D10: Founder working assumption | F10: Founder Assumption
A11: Insurance / risk reserve | B11: 10 | C11: ₹ / journey | D11: Founder working assumption | F11: Founder Assumption
A12: WhatsApp / SMS / communication | B12: 0.5 | C12: ₹ / journey | D12: Founder working assumption | F12: Founder Assumption
A13: BGV + training allocation | B13: 0 | C13: ₹ / journey | D13: Founder working assumption | F13: Founder Assumption
A14: Refund / service recovery reserve | B14: 36 | C14: ₹ / journey | D14: Founder working assumption | F14: Founder Assumption
A15: Average third-party cab actual | B15: ='Global Pricing Config'!$B$10 -> 500 | C15: ₹ / journey | D15: Founder working assumption for Case 2 | F15: Founder Assumption
A16: Transport coordination fee | B16: ='Global Pricing Config'!$B$9 -> 149 | C16: ₹ / journey | D16: Founder working assumption for Case 2 | F16: Founder Assumption
A17: GST on transport coordination fee | B17: 0 | C17: % | D17: Set to applicable rate after CA confirmation | F17: Market Test / CA Confirmation
A18: Transport ops / booking support | B18: 10 | C18: ₹ / journey | D18: Founder working assumption | F18: Founder Assumption
A19: Legacy extended-hour price (inactive) | B19: ='MVP1 Pricing & SKU'!$B$8 -> 269 | C19: ₹ / hour | D19: Historical assumption only. Not used in current MVP pricing engine. | F19: Founder Assumption
A20: New customer acquisition cost (sensitivity only) | B20: 299 | C20: ₹ / new family | D20: Illustrative founder assumption for repeat-rate sensitivity | F20: Founder Assumption
A21: Base package hours (sensitivity only) | B21: 4 | C21: hours | D21: Used only in additional-hour sensitivity | F21: Founder Assumption
A22: Minimum booking hours (MVP1) | B22: ='Global Pricing Config'!$B$6 -> 2 | C22: hours | D22: Linked to MVP1 Pricing & SKU | F22: Founder Assumption
A24: PAYROLL ANGEL ECONOMICS
A25: Active payroll Angels | B25: 3 | C25: Angels | D25: Founder Assumption | E25: Initial payroll team assumption | F25: =D25 -> Founder Assumption
A26: Monthly salary / Angel | B26: 14000 | C26: ₹ / Angel / month | D26: Founder Assumption | E26: Based on founder working plan | F26: =D26 -> Founder Assumption
A27: Angel working days / month | B27: 26 | C27: days | D27: Founder Assumption | E27: Editable | F27: =D27 -> Founder Assumption
A28: Scheduled hours / Angel / day | B28: 8 | C28: hours | D28: Founder Assumption | E28: Editable | F28: =D28 -> Founder Assumption
A29: Target productive utilization | B29: 0.65 | C29: % | D29: Founder Assumption | E29: Planning utilization target | F29: =D29 -> Founder Assumption
A30: Monthly Angel payroll | B30: =B25*B26 -> 42000 | C30: ₹ / month | D30: Derived Formula | E30: Active payroll Angels × salary / Angel | F30: =D30 -> Derived Formula
A31: Available Angel hours / month | B31: =B25*B27*B28 -> 624 | C31: hours / month | D31: Derived Formula | E31: Angels × days × scheduled hours | F31: =D31 -> Derived Formula
A32: Target productive Angel hours / month | B32: =B31*B29 -> 405.6 | C32: hours / month | D32: Derived Formula | E32: Available hours × target utilization | F32: =D32 -> Derived Formula
A33: Target fully loaded Angel cost / productive hour | B33: =IF(B32=0,0,B30/B32) -> 103.5503 | C33: ₹ / productive hour | D33: Derived Formula | E33: Payroll ÷ target productive hours | F33: =D33 -> Derived Formula
A34: Current productive Angel hours / month | B34: ='Whitefield Monthly Projection'!$Q$19*'Whitefield Monthly Projection'!$Q$15 -> 173.8044 | C34: hours / month | D34: Derived Formula | E34: Current completed journeys × weighted avg duration | F34: =D34 -> Derived Formula
A35: Current fully loaded Angel cost / productive hour | B35: =IF(B34=0,0,B30/B34) -> 241.65096 | C35: ₹ / productive hour | D35: Derived Formula | E35: Payroll ÷ current productive hours | F35: =D35 -> Derived Formula

Sheet Service Economics
A1: NivrāaCare — Dynamic Service Unit Economics | Incremental vs Fully Loaded Contribution
A2: Edit BLUE input cells (hours, service multiplier, fixed premium, Angel count, and optional overrides). MVP-1 pricing is controlled from 'MVP1 Pricing & SKU'; expected NC loyalty cost is controlled from 'NC Credits'. Overnight / very-long-duration rows are marked manual.
A4: Service | B4: Category | C4: Hours | D4: Rate Multiplier | E4: Fixed Premium / Fee | F4: No. of Angels | G4: Angel Cost/Hr Override | H4: Cab Cost Override | I4: Coord. Fee Override | J4: Effective Service Rate / Hr | K4: Customer Service Price (Incl GST; ₹299 × multiplier × billable hours + ₹199 fee) | L4: Net Service Revenue | M4: Effective Angel Cost/Hr | N4: Angel Cost | O4: Payment Platform Cost | P4: Other Variable Care Cost | Q4: CASE 1 Variable Delivery Cost | R4: CASE 1 Contribution Before Fixed Costs | S4: CASE 1 Contribution Margin | T4: Effective 3P Cab Cost | U4: Effective Coordination Fee | V4: Customer Transport Charge | W4: Transport Payment Cost | X4: Transport Ops Cost | Y4: Net Transport Coordination Contribution | Z4: CASE 2 Total Customer Outflow | AA4: CASE 2 Total Direct Cash Cost | AB4: CASE 2 Contribution Before Fixed Costs | AC4: CASE 2 Profit Uplift | AD4: CASE 2 Contribution Margin | AE4: Contribution / Service Hour C1 | AF4: Contribution / Service Hour C2 | AG4: Expected NC Loyalty Cost | AH4: Pricing Mode | AI4: Incremental Angel Cost / Hr | AJ4: Target Fully Loaded Angel Cost / Hr | AK4: Target Fully Loaded Angel Cost | AL4: CASE 1 Fully Loaded Contribution | AM4: CASE 1 Fully Loaded Margin | AN4: CASE 2 Fully Loaded Contribution | AO4: CASE 2 Fully Loaded Margin | AP4: Fully Loaded Contribution / Angel Hr | AQ4: Recurring / Strategic Potential | AR4: Multiplier Reason
A5: Hospital Visit | B5: Medical Visit | C5: 4 | D5: 1 | E5: 0 | F5: 1 | J5: ='MVP1 Pricing & SKU'!$B$7*D5 -> 299 | K5: 1395 | L5: =K5/(1+'Global Inputs'!$B$7) -> 1182.2034 | M5: =IF(G5="",'Global Inputs'!$B$6,G5) -> 0 | N5: =C5*F5*M5 -> 0 | O5: =K5*'Global Inputs'!$B$8+'Global Inputs'!$B$9 -> 0 | P5: =SUM('Global Inputs'!$B$10:$B$14) -> 56.5 | Q5: =SUM(N5:P5)+AG5 -> 105.325 | R5: =L5-Q5 -> 1076.8784 | S5: =IF(L5=0,0,R5/L5) -> 0.91090789 | T5: =IF(H5="",'Global Inputs'!$B$15,H5) -> 500 | U5: =IF(I5="",'Global Inputs'!$B$16,I5) -> 149 | V5: =T5+U5 -> 649 | W5: =V5*'Global Inputs'!$B$8 -> 0 | X5: ='Global Inputs'!$B$18 -> 10 | Y5: =U5/(1+'Global Inputs'!$B$17)-W5-X5 -> 139 | Z5: =K5+V5 -> 2044 | AA5: =Q5+T5+W5+X5 -> 615.325 | AB5: =R5+Y5 -> 1215.8784 | AC5: =AB5-R5 -> 139 | AD5: 0.91336786 | AE5: =IF(C5=0,0,R5/C5) -> 269.2196 | AF5: =IF(C5=0,0,AB5/C5) -> 303.9696 | AG5: =L5*'NC Credits'!$B$15 -> 48.825 | AH5: =IF(OR(ISNUMBER(SEARCH("Overnight",A5)),ISNUMBER(SEARCH("Multi-Day",A5)),ISNUMBER(SEARCH("Medical Tourism",A5))),"MANUAL","AUTO") -> AUTO | AI5: =M5 -> 0 | AJ5: ='Global Inputs'!$B$33 -> 103.5503 | AK5: =C5*F5*AJ5 -> 414.20118 | AL5: =R5+N5-AK5 -> 662.67721 | AM5: =IF(L5=0,0,AL5/L5) -> 0.56054416 | AN5: =AB5+N5-AK5 -> 801.67721 | AO5: =IF((L5+U5/(1+'Global Inputs'!$B$17))=0,0,AN5/(L5+U5/(1+'Global Inputs'!$B$17))) -> 0.60221993 | AP5: =IF(C5*F5=0,0,AL5/(C5*F5)) -> 165.6693 | AQ5: 5 | AR5: Full journey: home → facility → return / safe handover
A6: Hospital Visit — Concierge at Hospital | B6: Medical Visit | C6: 3 | D6: 0.8 | E6: 0 | F6: 1 | J6: ='MVP1 Pricing & SKU'!$B$7*D6 -> 239.2 | K6: 916.6 | L6: =K6/(1+'Global Inputs'!$B$7) -> 776.77966 | M6: =IF(G6="",'Global Inputs'!$B$6,G6) -> 0 | N6: =C6*F6*M6 -> 0 | O6: =K6*'Global Inputs'!$B$8+'Global Inputs'!$B$9 -> 0 | P6: =SUM('Global Inputs'!$B$10:$B$14) -> 56.5 | Q6: =SUM(N6:P6)+AG6 -> 88.581 | R6: =L6-Q6 -> 688.19866 | S6: =IF(L6=0,0,R6/L6) -> 0.8859638 | T6: =IF(H6="",'Global Inputs'!$B$15,H6) -> 500 | U6: =IF(I6="",'Global Inputs'!$B$16,I6) -> 149 | V6: =T6+U6 -> 649 | W6: =V6*'Global Inputs'!$B$8 -> 0 | X6: ='Global Inputs'!$B$18 -> 10 | Y6: =U6/(1+'Global Inputs'!$B$17)-W6-X6 -> 139 | Z6: =K6+V6 -> 1565.6 | AA6: =Q6+T6+W6+X6 -> 598.581 | AB6: =R6+Y6 -> 827.19866 | AC6: =AB6-R6 -> 139 | AD6: 0.8935157 | AE6: =IF(C6=0,0,R6/C6) -> 229.39955 | AF6: =IF(C6=0,0,AB6/C6) -> 275.73289 | AG6: =L6*'NC Credits'!$B$15 -> 32.081 | AH6: =IF(OR(ISNUMBER(SEARCH("Overnight",A6)),ISNUMBER(SEARCH("Multi-Day",A6)),ISNUMBER(SEARCH("Medical Tourism",A6))),"MANUAL","AUTO") -> AUTO | AI6: =M6 -> 0 | AJ6: ='Global Inputs'!$B$33 -> 103.5503 | AK6: =C6*F6*AJ6 -> 310.65089 | AL6: =R6+N6-AK6 -> 377.54777 | AM6: =IF(L6=0,0,AL6/L6) -> 0.4860423 | AN6: =AB6+N6-AK6 -> 516.54777 | AO6: =IF((L6+U6/(1+'Global Inputs'!$B$17))=0,0,AN6/(L6+U6/(1+'Global Inputs'!$B$17))) -> 0.55795973 | AP6: =IF(C6*F6=0,0,AL6/(C6*F6)) -> 125.84926 | AQ6: 4 | AR6: Hospital-only support; reduced travel and handover responsibility
A7: Clinic Visit | B7: Medical Visit | C7: 2 | D7: 0.9 | E7: 0 | F7: 1 | J7: ='MVP1 Pricing & SKU'!$B$7*D7 -> 269.1 | K7: 737.2 | L7: =K7/(1+'Global Inputs'!$B$7) -> 624.74576 | M7: =IF(G7="",'Global Inputs'!$B$6,G7) -> 0 | N7: =C7*F7*M7 -> 0 | O7: =K7*'Global Inputs'!$B$8+'Global Inputs'!$B$9 -> 0 | P7: =SUM('Global Inputs'!$B$10:$B$14) -> 56.5 | Q7: =SUM(N7:P7)+AG7 -> 82.302 | R7: =L7-Q7 -> 542.44376 | S7: =IF(L7=0,0,R7/L7) -> 0.86826321 | T7: =IF(H7="",'Global Inputs'!$B$15,H7) -> 500 | U7: =IF(I7="",'Global Inputs'!$B$16,I7) -> 149 | V7: =T7+U7 -> 649 | W7: =V7*'Global Inputs'!$B$8 -> 0 | X7: ='Global Inputs'!$B$18 -> 10 | Y7: =U7/(1+'Global Inputs'!$B$17)-W7-X7 -> 139 | Z7: =K7+V7 -> 1386.2 | AA7: =Q7+T7+W7+X7 -> 592.302 | AB7: =R7+Y7 -> 681.44376 | AC7: =AB7-R7 -> 139 | AD7: 0.88070759 | AE7: =IF(C7=0,0,R7/C7) -> 271.22188 | AF7: =IF(C7=0,0,AB7/C7) -> 340.72188 | AG7: =L7*'NC Credits'!$B$15 -> 25.802 | AH7: =IF(OR(ISNUMBER(SEARCH("Overnight",A7)),ISNUMBER(SEARCH("Multi-Day",A7)),ISNUMBER(SEARCH("Medical Tourism",A7))),"MANUAL","AUTO") -> AUTO | AI7: =M7 -> 0 | AJ7: ='Global Inputs'!$B$33 -> 103.5503 | AK7: =C7*F7*AJ7 -> 207.10059 | AL7: =R7+N7-AK7 -> 335.34317 | AM7: =IF(L7=0,0,AL7/L7) -> 0.53676742 | AN7: =AB7+N7-AK7 -> 474.34317 | AO7: =IF((L7+U7/(1+'Global Inputs'!$B$17))=0,0,AN7/(L7+U7/(1+'Global Inputs'!$B$17))) -> 0.61304784 | AP7: =IF(C7*F7=0,0,AL7/(C7*F7)) -> 167.67159 | AQ7: 4 | AR7: Shorter, lower-complexity outpatient journey
A8: Diagnostic Center Visit | B8: Medical Visit | C8: 3 | D8: 0.85 | E8: 0 | F8: 1 | J8: ='MVP1 Pricing & SKU'!$B$7*D8 -> 254.15 | K8: 961.45 | L8: =K8/(1+'Global Inputs'!$B$7) -> 814.78814 | M8: =IF(G8="",'Global Inputs'!$B$6,G8) -> 0 | N8: =C8*F8*M8 -> 0 | O8: =K8*'Global Inputs'!$B$8+'Global Inputs'!$B$9 -> 0 | P8: =SUM('Global Inputs'!$B$10:$B$14) -> 56.5 | Q8: =SUM(N8:P8)+AG8 -> 90.15075 | R8: =L8-Q8 -> 724.63739 | S8: =IF(L8=0,0,R8/L8) -> 0.88935682 | T8: =IF(H8="",'Global Inputs'!$B$15,H8) -> 500 | U8: =IF(I8="",'Global Inputs'!$B$16,I8) -> 149 | V8: =T8+U8 -> 649 | W8: =V8*'Global Inputs'!$B$8 -> 0 | X8: ='Global Inputs'!$B$18 -> 10 | Y8: =U8/(1+'Global Inputs'!$B$17)-W8-X8 -> 139 | Z8: =K8+V8 -> 1610.45 | AA8: =Q8+T8+W8+X8 -> 600.15075 | AB8: =R8+Y8 -> 863.63739 | AC8: =AB8-R8 -> 139 | AD8: 0.89608634 | AE8: =IF(C8=0,0,R8/C8) -> 241.5458 | AF8: =IF(C8=0,0,AB8/C8) -> 287.87913 | AG8: =L8*'NC Credits'!$B$15 -> 33.65075 | AH8: =IF(OR(ISNUMBER(SEARCH("Overnight",A8)),ISNUMBER(SEARCH("Multi-Day",A8)),ISNUMBER(SEARCH("Medical Tourism",A8))),"MANUAL","AUTO") -> AUTO | AI8: =M8 -> 0 | AJ8: ='Global Inputs'!$B$33 -> 103.5503 | AK8: =C8*F8*AJ8 -> 310.65089 | AL8: =R8+N8-AK8 -> 413.9865 | AM8: =IF(L8=0,0,AL8/L8) -> 0.50809097 | AN8: =AB8+N8-AK8 -> 552.9865 | AO8: =IF((L8+U8/(1+'Global Inputs'!$B$17))=0,0,AN8/(L8+U8/(1+'Global Inputs'!$B$17))) -> 0.57376355 | AP8: =IF(C8*F8=0,0,AL8/(C8*F8)) -> 137.9955 | AQ8: 4 | AR8: Generally simpler navigation / diagnostic-only workflow
A9: Health Check-up Concierge | B9: Medical Visit | C9: 5 | D9: 0.9 | E9: 0 | F9: 1 | J9: ='MVP1 Pricing & SKU'!$B$7*D9 -> 269.1 | K9: 1544.5 | L9: =K9/(1+'Global Inputs'!$B$7) -> 1308.8983 | M9: =IF(G9="",'Global Inputs'!$B$6,G9) -> 0 | N9: =C9*F9*M9 -> 0 | O9: =K9*'Global Inputs'!$B$8+'Global Inputs'!$B$9 -> 0 | P9: =SUM('Global Inputs'!$B$10:$B$14) -> 56.5 | Q9: =SUM(N9:P9)+AG9 -> 110.5575 | R9: =L9-Q9 -> 1198.3408 | S9: =IF(L9=0,0,R9/L9) -> 0.91553393 | T9: =IF(H9="",'Global Inputs'!$B$15,H9) -> 500 | U9: =IF(I9="",'Global Inputs'!$B$16,I9) -> 149 | V9: =T9+U9 -> 649 | W9: =V9*'Global Inputs'!$B$8 -> 0 | X9: ='Global Inputs'!$B$18 -> 10 | Y9: =U9/(1+'Global Inputs'!$B$17)-W9-X9 -> 139 | Z9: =K9+V9 -> 2193.5 | AA9: =Q9+T9+W9+X9 -> 620.5575 | AB9: =R9+Y9 -> 1337.3408 | AC9: =AB9-R9 -> 139 | AD9: 0.91730733 | AE9: =IF(C9=0,0,R9/C9) -> 239.66816 | AF9: =IF(C9=0,0,AB9/C9) -> 267.46816 | AG9: =L9*'NC Credits'!$B$15 -> 54.0575 | AH9: =IF(OR(ISNUMBER(SEARCH("Overnight",A9)),ISNUMBER(SEARCH("Multi-Day",A9)),ISNUMBER(SEARCH("Medical Tourism",A9))),"MANUAL","AUTO") -> AUTO | AI9: =M9 -> 0 | AJ9: ='Global Inputs'!$B$33 -> 103.5503 | AK9: =C9*F9*AJ9 -> 517.75148 | AL9: =R9+N9-AK9 -> 680.58933 | AM9: =IF(L9=0,0,AL9/L9) -> 0.51997113 | AN9: =AB9+N9-AK9 -> 819.58933 | AO9: =IF((L9+U9/(1+'Global Inputs'!$B$17))=0,0,AN9/(L9+U9/(1+'Global Inputs'!$B$17))) -> 0.56217181 | AP9: =IF(C9*F9=0,0,AL9/(C9*F9)) -> 136.11787 | AQ9: 3 | AR9: Structured preventive-care journey; moderate coordination
A10: Hospital Admission Concierge | B10: Hospital Support | C10: 4 | D10: 1.15 | E10: 0 | F10: 1 | J10: ='MVP1 Pricing & SKU'!$B$7*D10 -> 343.85 | K10: 1574.4 | L10: =K10/(1+'Global Inputs'!$B$7) -> 1334.2373 | M10: =IF(G10="",'Global Inputs'!$B$6,G10) -> 0 | N10: =C10*F10*M10 -> 0 | O10: =K10*'Global Inputs'!$B$8+'Global Inputs'!$B$9 -> 0 | P10: =SUM('Global Inputs'!$B$10:$B$14) -> 56.5 | Q10: =SUM(N10:P10)+AG10 -> 111.604 | R10: =L10-Q10 -> 1222.6333 | S10: =IF(L10=0,0,R10/L10) -> 0.91635371 | T10: =IF(H10="",'Global Inputs'!$B$15,H10) -> 500 | U10: =IF(I10="",'Global Inputs'!$B$16,I10) -> 149 | V10: =T10+U10 -> 649 | W10: =V10*'Global Inputs'!$B$8 -> 0 | X10: ='Global Inputs'!$B$18 -> 10 | Y10: =U10/(1+'Global Inputs'!$B$17)-W10-X10 -> 139 | Z10: =K10+V10 -> 2223.4 | AA10: =Q10+T10+W10+X10 -> 621.604 | AB10: =R10+Y10 -> 1361.6333 | AC10: =AB10-R10 -> 139 | AD10: 0.91801447 | AE10: =IF(C10=0,0,R10/C10) -> 305.65832 | AF10: =IF(C10=0,0,AB10/C10) -> 340.40832 | AG10: =L10*'NC Credits'!$B$15 -> 55.104 | AH10: =IF(OR(ISNUMBER(SEARCH("Overnight",A10)),ISNUMBER(SEARCH("Multi-Day",A10)),ISNUMBER(SEARCH("Medical Tourism",A10))),"MANUAL","AUTO") -> AUTO | AI10: =M10 -> 0 | AJ10: ='Global Inputs'!$B$33 -> 103.5503 | AK10: =C10*F10*AJ10 -> 414.20118 | AL10: =R10+N10-AK10 -> 808.4321 | AM10: =IF(L10=0,0,AL10/L10) -> 0.60591329 | AN10: =AB10+N10-AK10 -> 947.4321 | AO10: =IF((L10+U10/(1+'Global Inputs'!$B$17))=0,0,AN10/(L10+U10/(1+'Global Inputs'!$B$17))) -> 0.63875963 | AP10: =IF(C10*F10=0,0,AL10/(C10*F10)) -> 202.10803 | AQ10: 3 | AR10: Higher coordination, documentation and handoff complexity
A11: Hospital Discharge Concierge | B11: Hospital Support | C11: 4 | D11: 1.1 | E11: 0 | F11: 1 | J11: ='MVP1 Pricing & SKU'!$B$7*D11 -> 328.9 | K11: 1514.6 | L11: =K11/(1+'Global Inputs'!$B$7) -> 1283.5593 | M11: =IF(G11="",'Global Inputs'!$B$6,G11) -> 0 | N11: =C11*F11*M11 -> 0 | O11: =K11*'Global Inputs'!$B$8+'Global Inputs'!$B$9 -> 0 | P11: =SUM('Global Inputs'!$B$10:$B$14) -> 56.5 | Q11: =SUM(N11:P11)+AG11 -> 109.511 | R11: =L11-Q11 -> 1174.0483 | S11: =IF(L11=0,0,R11/L11) -> 0.91468178 | T11: =IF(H11="",'Global Inputs'!$B$15,H11) -> 500 | U11: =IF(I11="",'Global Inputs'!$B$16,I11) -> 149 | V11: =T11+U11 -> 649 | W11: =V11*'Global Inputs'!$B$8 -> 0 | X11: ='Global Inputs'!$B$18 -> 10 | Y11: =U11/(1+'Global Inputs'!$B$17)-W11-X11 -> 139 | Z11: =K11+V11 -> 2163.6 | AA11: =Q11+T11+W11+X11 -> 619.511 | AB11: =R11+Y11 -> 1313.0483 | AC11: =AB11-R11 -> 139 | AD11: 0.91657518 | AE11: =IF(C11=0,0,R11/C11) -> 293.51208 | AF11: =IF(C11=0,0,AB11/C11) -> 328.26208 | AG11: =L11*'NC Credits'!$B$15 -> 53.011 | AH11: =IF(OR(ISNUMBER(SEARCH("Overnight",A11)),ISNUMBER(SEARCH("Multi-Day",A11)),ISNUMBER(SEARCH("Medical Tourism",A11))),"MANUAL","AUTO") -> AUTO | AI11: =M11 -> 0 | AJ11: ='Global Inputs'!$B$33 -> 103.5503 | AK11: =C11*F11*AJ11 -> 414.20118 | AL11: =R11+N11-AK11 -> 759.84714 | AM11: =IF(L11=0,0,AL11/L11) -> 0.59198443 | AN11: =AB11+N11-AK11 -> 898.84714 | AO11: =IF((L11+U11/(1+'Global Inputs'!$B$17))=0,0,AN11/(L11+U11/(1+'Global Inputs'!$B$17))) -> 0.62744148 | AP11: =IF(C11*F11=0,0,AL11/(C11*F11)) -> 189.96178 | AQ11: 3 | AR11: Higher coordination and post-discharge handover responsibility
A12: Overnight Hospital Concierge | B12: Hospital Support | C12: 12 | D12: 0.85 | E12: 299 | F12: 1 | J12: ='MVP1 Pricing & SKU'!$B$7*D12 -> 254.15 | K12: 3547.8 | L12: =K12/(1+'Global Inputs'!$B$7) -> 3006.6102 | M12: =IF(G12="",'Global Inputs'!$B$6,G12) -> 0 | N12: =C12*F12*M12 -> 0 | O12: =K12*'Global Inputs'!$B$8+'Global Inputs'!$B$9 -> 0 | P12: =SUM('Global Inputs'!$B$10:$B$14) -> 56.5 | Q12: =SUM(N12:P12)+AG12 -> 180.673 | R12: =L12-Q12 -> 2825.9372 | S12: =IF(L12=0,0,R12/L12) -> 0.93990807 | T12: =IF(H12="",'Global Inputs'!$B$15,H12) -> 500 | U12: =IF(I12="",'Global Inputs'!$B$16,I12) -> 149 | V12: =T12+U12 -> 649 | W12: =V12*'Global Inputs'!$B$8 -> 0 | X12: ='Global Inputs'!$B$18 -> 10 | Y12: =U12/(1+'Global Inputs'!$B$17)-W12-X12 -> 139 | Z12: =K12+V12 -> 4196.8 | AA12: =Q12+T12+W12+X12 -> 690.673 | AB12: =R12+Y12 -> 2964.9372 | AC12: =AB12-R12 -> 139 | AD12: 0.9395765 | AE12: =IF(C12=0,0,R12/C12) -> 235.49476 | AF12: =IF(C12=0,0,AB12/C12) -> 247.0781 | AG12: =L12*'NC Credits'!$B$15 -> 124.173 | AH12: =IF(OR(ISNUMBER(SEARCH("Overnight",A12)),ISNUMBER(SEARCH("Multi-Day",A12)),ISNUMBER(SEARCH("Medical Tourism",A12))),"MANUAL","AUTO") -> MANUAL | AI12: =M12 -> 0 | AJ12: ='Global Inputs'!$B$33 -> 103.5503 | AK12: =C12*F12*AJ12 -> 1242.6036 | AL12: =R12+N12-AK12 -> 1583.3336 | AM12: =IF(L12=0,0,AL12/L12) -> 0.52661753 | AN12: =AB12+N12-AK12 -> 1722.3336 | AO12: =IF((L12+U12/(1+'Global Inputs'!$B$17))=0,0,AN12/(L12+U12/(1+'Global Inputs'!$B$17))) -> 0.5458005 | AP12: =IF(C12*F12=0,0,AL12/(C12*F12)) -> 131.94447 | AQ12: 2 | AR12: Long-duration service; manual pricing should supersede multiplier
A13: Multi-Day Hospital Concierge (per 12h shift) | B13: Hospital Support | C13: 12 | D13: 0.85 | E13: 299 | F13: 1 | J13: ='MVP1 Pricing & SKU'!$B$7*D13 -> 254.15 | K13: 3547.8 | L13: =K13/(1+'Global Inputs'!$B$7) -> 3006.6102 | M13: =IF(G13="",'Global Inputs'!$B$6,G13) -> 0 | N13: =C13*F13*M13 -> 0 | O13: =K13*'Global Inputs'!$B$8+'Global Inputs'!$B$9 -> 0 | P13: =SUM('Global Inputs'!$B$10:$B$14) -> 56.5 | Q13: =SUM(N13:P13)+AG13 -> 180.673 | R13: =L13-Q13 -> 2825.9372 | S13: =IF(L13=0,0,R13/L13) -> 0.93990807 | T13: =IF(H13="",'Global Inputs'!$B$15,H13) -> 500 | U13: =IF(I13="",'Global Inputs'!$B$16,I13) -> 149 | V13: =T13+U13 -> 649 | W13: =V13*'Global Inputs'!$B$8 -> 0 | X13: ='Global Inputs'!$B$18 -> 10 | Y13: =U13/(1+'Global Inputs'!$B$17)-W13-X13 -> 139 | Z13: =K13+V13 -> 4196.8 | AA13: =Q13+T13+W13+X13 -> 690.673 | AB13: =R13+Y13 -> 2964.9372 | AC13: =AB13-R13 -> 139 | AD13: 0.9395765 | AE13: =IF(C13=0,0,R13/C13) -> 235.49476 | AF13: =IF(C13=0,0,AB13/C13) -> 247.0781 | AG13: =L13*'NC Credits'!$B$15 -> 124.173 | AH13: =IF(OR(ISNUMBER(SEARCH("Overnight",A13)),ISNUMBER(SEARCH("Multi-Day",A13)),ISNUMBER(SEARCH("Medical Tourism",A13))),"MANUAL","AUTO") -> MANUAL | AI13: =M13 -> 0 | AJ13: ='Global Inputs'!$B$33 -> 103.5503 | AK13: =C13*F13*AJ13 -> 1242.6036 | AL13: =R13+N13-AK13 -> 1583.3336 | AM13: =IF(L13=0,0,AL13/L13) -> 0.52661753 | AN13: =AB13+N13-AK13 -> 1722.3336 | AO13: =IF((L13+U13/(1+'Global Inputs'!$B$17))=0,0,AN13/(L13+U13/(1+'Global Inputs'!$B$17))) -> 0.5458005 | AP13: =IF(C13*F13=0,0,AL13/(C13*F13)) -> 131.94447 | AQ13: 2 | AR13: Long-duration service; manual shift pricing
A14: Day Surgery / Procedure Concierge | B14: Procedure & Treatment | C14: 6 | D14: 1.2 | E14: 0 | F14: 1 | J14: ='MVP1 Pricing & SKU'!$B$7*D14 -> 358.8 | K14: 2351.8 | L14: =K14/(1+'Global Inputs'!$B$7) -> 1993.0508 | M14: =IF(G14="",'Global Inputs'!$B$6,G14) -> 0 | N14: =C14*F14*M14 -> 0 | O14: =K14*'Global Inputs'!$B$8+'Global Inputs'!$B$9 -> 0 | P14: =SUM('Global Inputs'!$B$10:$B$14) -> 56.5 | Q14: =SUM(N14:P14)+AG14 -> 138.813 | R14: =L14-Q14 -> 1854.2378 | S14: =IF(L14=0,0,R14/L14) -> 0.9303515 | T14: =IF(H14="",'Global Inputs'!$B$15,H14) -> 500 | U14: =IF(I14="",'Global Inputs'!$B$16,I14) -> 149 | V14: =T14+U14 -> 649 | W14: =V14*'Global Inputs'!$B$8 -> 0 | X14: ='Global Inputs'!$B$18 -> 10 | Y14: =U14/(1+'Global Inputs'!$B$17)-W14-X14 -> 139 | Z14: =K14+V14 -> 3000.8 | AA14: =Q14+T14+W14+X14 -> 648.813 | AB14: =R14+Y14 -> 1993.2378 | AC14: =AB14-R14 -> 139 | AD14: 0.93052779 | AE14: =IF(C14=0,0,R14/C14) -> 309.03964 | AF14: =IF(C14=0,0,AB14/C14) -> 332.20631 | AG14: =L14*'NC Credits'!$B$15 -> 82.313 | AH14: =IF(OR(ISNUMBER(SEARCH("Overnight",A14)),ISNUMBER(SEARCH("Multi-Day",A14)),ISNUMBER(SEARCH("Medical Tourism",A14))),"MANUAL","AUTO") -> AUTO | AI14: =M14 -> 0 | AJ14: ='Global Inputs'!$B$33 -> 103.5503 | AK14: =C14*F14*AJ14 -> 621.30178 | AL14: =R14+N14-AK14 -> 1232.9361 | AM14: =IF(L14=0,0,AL14/L14) -> 0.61861747 | AN14: =AB14+N14-AK14 -> 1371.9361 | AO14: =IF((L14+U14/(1+'Global Inputs'!$B$17))=0,0,AN14/(L14+U14/(1+'Global Inputs'!$B$17))) -> 0.64047783 | AP14: =IF(C14*F14=0,0,AL14/(C14*F14)) -> 205.48935 | AQ14: 3 | AR14: Procedure-day complexity and extended coordination
A15: Pre-Surgery Concierge | B15: Procedure & Treatment | C15: 4 | D15: 1.1 | E15: 0 | F15: 1 | J15: ='MVP1 Pricing & SKU'!$B$7*D15 -> 328.9 | K15: 1514.6 | L15: =K15/(1+'Global Inputs'!$B$7) -> 1283.5593 | M15: =IF(G15="",'Global Inputs'!$B$6,G15) -> 0 | N15: =C15*F15*M15 -> 0 | O15: =K15*'Global Inputs'!$B$8+'Global Inputs'!$B$9 -> 0 | P15: =SUM('Global Inputs'!$B$10:$B$14) -> 56.5 | Q15: =SUM(N15:P15)+AG15 -> 109.511 | R15: =L15-Q15 -> 1174.0483 | S15: =IF(L15=0,0,R15/L15) -> 0.91468178 | T15: =IF(H15="",'Global Inputs'!$B$15,H15) -> 500 | U15: =IF(I15="",'Global Inputs'!$B$16,I15) -> 149 | V15: =T15+U15 -> 649 | W15: =V15*'Global Inputs'!$B$8 -> 0 | X15: ='Global Inputs'!$B$18 -> 10 | Y15: =U15/(1+'Global Inputs'!$B$17)-W15-X15 -> 139 | Z15: =K15+V15 -> 2163.6 | AA15: =Q15+T15+W15+X15 -> 619.511 | AB15: =R15+Y15 -> 1313.0483 | AC15: =AB15-R15 -> 139 | AD15: 0.91657518 | AE15: =IF(C15=0,0,R15/C15) -> 293.51208 | AF15: =IF(C15=0,0,AB15/C15) -> 328.26208 | AG15: =L15*'NC Credits'!$B$15 -> 53.011 | AH15: =IF(OR(ISNUMBER(SEARCH("Overnight",A15)),ISNUMBER(SEARCH("Multi-Day",A15)),ISNUMBER(SEARCH("Medical Tourism",A15))),"MANUAL","AUTO") -> AUTO | AI15: =M15 -> 0 | AJ15: ='Global Inputs'!$B$33 -> 103.5503 | AK15: =C15*F15*AJ15 -> 414.20118 | AL15: =R15+N15-AK15 -> 759.84714 | AM15: =IF(L15=0,0,AL15/L15) -> 0.59198443 | AN15: =AB15+N15-AK15 -> 898.84714 | AO15: =IF((L15+U15/(1+'Global Inputs'!$B$17))=0,0,AN15/(L15+U15/(1+'Global Inputs'!$B$17))) -> 0.62744148 | AP15: =IF(C15*F15=0,0,AL15/(C15*F15)) -> 189.96178 | AQ15: 2 | AR15: Preparation, records and multi-party coordination
A16: Post-Surgery Follow-up | B16: Procedure & Treatment | C16: 3 | D16: 1 | E16: 0 | F16: 1 | J16: ='MVP1 Pricing & SKU'!$B$7*D16 -> 299 | K16: 1096 | L16: =K16/(1+'Global Inputs'!$B$7) -> 928.81356 | M16: =IF(G16="",'Global Inputs'!$B$6,G16) -> 0 | N16: =C16*F16*M16 -> 0 | O16: =K16*'Global Inputs'!$B$8+'Global Inputs'!$B$9 -> 0 | P16: =SUM('Global Inputs'!$B$10:$B$14) -> 56.5 | Q16: =SUM(N16:P16)+AG16 -> 94.86 | R16: =L16-Q16 -> 833.95356 | S16: =IF(L16=0,0,R16/L16) -> 0.89786971 | T16: =IF(H16="",'Global Inputs'!$B$15,H16) -> 500 | U16: =IF(I16="",'Global Inputs'!$B$16,I16) -> 149 | V16: =T16+U16 -> 649 | W16: =V16*'Global Inputs'!$B$8 -> 0 | X16: ='Global Inputs'!$B$18 -> 10 | Y16: =U16/(1+'Global Inputs'!$B$17)-W16-X16 -> 139 | Z16: =K16+V16 -> 1745 | AA16: =Q16+T16+W16+X16 -> 604.86 | AB16: =R16+Y16 -> 972.95356 | AC16: =AB16-R16 -> 139 | AD16: 0.90271045 | AE16: =IF(C16=0,0,R16/C16) -> 277.98452 | AF16: =IF(C16=0,0,AB16/C16) -> 324.31785 | AG16: =L16*'NC Credits'!$B$15 -> 38.36 | AH16: =IF(OR(ISNUMBER(SEARCH("Overnight",A16)),ISNUMBER(SEARCH("Multi-Day",A16)),ISNUMBER(SEARCH("Medical Tourism",A16))),"MANUAL","AUTO") -> AUTO | AI16: =M16 -> 0 | AJ16: ='Global Inputs'!$B$33 -> 103.5503 | AK16: =C16*F16*AJ16 -> 310.65089 | AL16: =R16+N16-AK16 -> 523.30267 | AM16: =IF(L16=0,0,AL16/L16) -> 0.56340981 | AN16: =AB16+N16-AK16 -> 662.30267 | AO16: =IF((L16+U16/(1+'Global Inputs'!$B$17))=0,0,AN16/(L16+U16/(1+'Global Inputs'!$B$17))) -> 0.61448723 | AP16: =IF(C16*F16=0,0,AL16/(C16*F16)) -> 174.43422 | AQ16: 3 | AR16: Standard follow-up journey with moderate coordination
... A34: Family Medical Update Concierge | B34: Continuing Care | C34: 3 | D34: 0.65 | E34: 0 | F34: 1 | J34: ='MVP1 Pricing & SKU'!$B$7*D34 -> 194.35 | K34: 782.05 | L34: =K34/(1+'Global Inputs'!$B$7) -> 662.75424 | M34: =IF(G34="",'Global Inputs'!$B$6,G34) -> 0 | N34: =C34*F34*M34 -> 0 | O34: =K34*'Global Inputs'!$B$8+'Global Inputs'!$B$9 -> 0 | P34: =SUM('Global Inputs'!$B$10:$B$14) -> 56.5 | Q34: =SUM(N34:P34)+AG34 -> 83.87175 | R34: =L34-Q34 -> 578.88249 | S34: =IF(L34=0,0,R34/L34) -> 0.8734497 | T34: =IF(H34="",'Global Inputs'!$B$15,H34) -> 500 | U34: =IF(I34="",'Global Inputs'!$B$16,I34) -> 149 | V34: =T34+U34 -> 649 | W34: =V34*'Global Inputs'!$B$8 -> 0 | X34: ='Global Inputs'!$B$18 -> 10 | Y34: =U34/(1+'Global Inputs'!$B$17)-W34-X34 -> 139 | Z34: =K34+V34 -> 1431.05 | AA34: =Q34+T34+W34+X34 -> 593.87175 | AB34: =R34+Y34 -> 717.88249 | AC34: =AB34-R34 -> 139 | AD34: 0.8843594 | AE34: =IF(C34=0,0,R34/C34) -> 192.96083 | AF34: =IF(C34=0,0,AB34/C34) -> 239.29416 | AG34: =L34*'NC Credits'!$B$15 -> 27.37175 | AH34: =IF(OR(ISNUMBER(SEARCH("Overnight",A34)),ISNUMBER(SEARCH("Multi-Day",A34)),ISNUMBER(SEARCH("Medical Tourism",A34))),"MANUAL","AUTO") -> AUTO | AI34: =M34 -> 0 | AJ34: ='Global Inputs'!$B$33 -> 103.5503 | AK34: =C34*F34*AJ34 -> 310.65089 | AL34: =R34+N34-AK34 -> 268.2316 | AM34: =IF(L34=0,0,AL34/L34) -> 0.40472257 | AN34: =AB34+N34-AK34 -> 407.2316 | AO34: =IF((L34+U34/(1+'Global Inputs'!$B$17))=0,0,AN34/(L34+U34/(1+'Global Inputs'!$B$17))) -> 0.50166859 | AP34: =IF(C34*F34=0,0,AL34/(C34*F34)) -> 89.410533 | AQ34: 5 | AR34: Communication-focused support; no full physical journey

Sheet Service Catalogue
A1: NivrāaCare — Medical Concierge Service Catalogue
A3: Service | B3: Category | C3: Typical Concierge Scope | D3: Clinical Boundary
A4: Hospital Visit | B4: Medical Visit | C4: Accompany patient, navigate registration/queues, coordinate visit, family updates, return handover. | D4: NivrāaCare concierge does not diagnose, prescribe, administer clinical treatment, or replace licensed medical professionals.
A5: Diagnostic Center Visit | B5: Medical Visit | C5: Accompany patient, navigate registration/queues, coordinate visit, family updates, return handover. | D5: NivrāaCare concierge does not diagnose, prescribe, administer clinical treatment, or replace licensed medical professionals.
A6: Clinic Visit | B6: Medical Visit | C6: Accompany patient, navigate registration/queues, coordinate visit, family updates, return handover. | D6: NivrāaCare concierge does not diagnose, prescribe, administer clinical treatment, or replace licensed medical professionals.
A7: Specialist Consultation | B7: Medical Visit | C7: Accompany patient, navigate registration/queues, coordinate visit, family updates, return handover. | D7: NivrāaCare concierge does not diagnose, prescribe, administer clinical treatment, or replace licensed medical professionals.
A8: Health Check-up Concierge | B8: Medical Visit | C8: Accompany patient, navigate registration/queues, coordinate visit, family updates, return handover. | D8: NivrāaCare concierge does not diagnose, prescribe, administer clinical treatment, or replace licensed medical professionals.
A9: Hospital Admission Concierge | B9: Hospital Support | C9: Admission/discharge/overnight non-clinical presence, logistics, documents, family communication. | D9: NivrāaCare concierge does not diagnose, prescribe, administer clinical treatment, or replace licensed medical professionals.
A10: Hospital Discharge Concierge | B10: Hospital Support | C10: Admission/discharge/overnight non-clinical presence, logistics, documents, family communication. | D10: NivrāaCare concierge does not diagnose, prescribe, administer clinical treatment, or replace licensed medical professionals.
A11: Overnight Hospital Concierge | B11: Hospital Support | C11: Admission/discharge/overnight non-clinical presence, logistics, documents, family communication. | D11: NivrāaCare concierge does not diagnose, prescribe, administer clinical treatment, or replace licensed medical professionals.
A12: Multi-Day Hospital Concierge (per 12h shift) | B12: Hospital Support | C12: Admission/discharge/overnight non-clinical presence, logistics, documents, family communication. | D12: NivrāaCare concierge does not diagnose, prescribe, administer clinical treatment, or replace licensed medical professionals.
A13: Day Surgery / Procedure Concierge | B13: Procedure & Treatment | C13: Pre/post procedure logistics, waiting coordination, non-clinical accompaniment and handover. | D13: NivrāaCare concierge does not diagnose, prescribe, administer clinical treatment, or replace licensed medical professionals.
A14: Pre-Surgery Concierge | B14: Procedure & Treatment | C14: Pre/post procedure logistics, waiting coordination, non-clinical accompaniment and handover. | D14: NivrāaCare concierge does not diagnose, prescribe, administer clinical treatment, or replace licensed medical professionals.
... A33: Family Medical Update Concierge | B33: Continuing Care | C33: Ongoing family coordination, scheduled follow-ups, authorised updates and continuity. | D33: NivrāaCare concierge does not diagnose, prescribe, administer clinical treatment, or replace licensed medical professionals.

Sheet Whitefield Monthly Projection
A1: NivrāaCare — Whitefield Monthly Revenue & Profit Projection
A2: Founder model for Whitefield-only launch. Service revenue flows from the MVP-1 hourly pricing engine: ₹299/hour × service-specific multiplier × billable hours + ₹199 fee, 2h minimum. ₹269 is retained only as a legacy reference and is not used in active pricing.
A4: Selected Scenario | B4: Conservative | F4: Scenario Driver | G4: Conservative | H4: Base | I4: Aggressive | J4: Selected | P4: Selected Scenario — Monthly Summary | U4: Variable Cost Breakdown
A5: Operating Input | B5: Value | F5: Active Angels | G5: 4 | H5: 5 | I5: 7 | J5: =IF($B$4="Conservative",G5,IF($B$4="Base",H5,I5)) -> 4 | P5: Demand | Q5: Value | U5: Variable Cost | V5: Monthly ₹ | W5: Driver
A6: Active Angels | B6: =J5 -> 4 | F6: Leads / day | G6: 6 | H6: 10 | I6: 16 | J6: =IF($B$4="Conservative",G6,IF($B$4="Base",H6,I6)) -> 6 | P6: Leads / month | Q6: =$B$11*$B$7 -> 180 | U6: Angel payouts | V6: =SUMPRODUCT(I37:I66,'Service Economics'!N5:N34) -> 0 | W6: Hours × Angel cost
A7: Operating days / month | B7: 30 | F7: Booking conversion | G7: 0.25 | H7: 0.35 | I7: 0.45 | J7: =IF($B$4="Conservative",G7,IF($B$4="Base",H7,I7)) -> 0.25 | P7: Confirmed journeys | Q7: =Q6*$B$12 -> 45 | U7: Payment platform — care service | V7: =SUMPRODUCT(I37:I66,'Service Economics'!O5:O34) -> 0 | W7: Service collections × fee
A8: Max working hours / Angel / day | B8: 8 | F8: Cancellation | G8: 0.12 | H8: 0.08 | I8: 0.06 | J8: =IF($B$4="Conservative",G8,IF($B$4="Base",H8,I8)) -> 0.12 | P8: Cancelled journeys | Q8: =Q7*$B$13 -> 5.4 | U8: Ops / support allocation | V8: =$Q$19*'Global Inputs'!$B$10 -> 376.2 | W8: Per completed journey
A9: Target Angel utilization | B9: 1 | F9: No-show / refund | G9: 0.05 | H9: 0.03 | I9: 0.02 | J9: =IF($B$4="Conservative",G9,IF($B$4="Base",H9,I9)) -> 0.05 | P9: No-show / refund journeys | Q9: =(Q7-Q8)*$B$14 -> 1.98 | U9: Insurance / risk reserve | V9: =$Q$19*'Global Inputs'!$B$11 -> 376.2 | W9: Per completed journey
A10: Avg journeys / Angel / day cap | B10: 1.8 | F10: Target utilization | G10: 0.5 | H10: 0.65 | I10: 0.8 | J10: =IF($B$4="Conservative",G10,IF($B$4="Base",H10,I10)) -> 0.5 | P10: Demand-completed journeys | Q10: =Q7-Q8-Q9 -> 37.62 | U10: WhatsApp / SMS | V10: =$Q$19*'Global Inputs'!$B$12 -> 18.81 | W10: Per completed journey
A11: Customer leads / enquiries per day | B11: =J6 -> 6 | F11: Case 2 transport mix | G11: 0.4 | H11: 0.6 | I11: 0.7 | J11: =IF($B$4="Conservative",G11,IF($B$4="Base",H11,I11)) -> 0.4 | U11: BGV + training allocation | V11: =$Q$19*'Global Inputs'!$B$13 -> 0 | W11: Per completed journey
A12: Booking conversion rate | B12: =J7 -> 0.25 | F12: Repeat journey mix | G12: 0.2 | H12: 0.3 | I12: 0.45 | J12: =IF($B$4="Conservative",G12,IF($B$4="Base",H12,I12)) -> 0.2 | P12: Capacity | Q12: Value | U12: Refund / service recovery reserve | V12: =$Q$19*'Global Inputs'!$B$14 -> 1354.32 | W12: Per completed journey
A13: Cancellation rate | B13: =J8 -> 0.12 | P13: Total Angel hours available | Q13: =$B$6*$B$7*$B$8 -> 960 | U13: Third-party cab actual | V13: =$B$16*SUMPRODUCT(I37:I66,'Service Economics'!T5:T34) -> 7524 | W13: Case 2 journeys
A14: No-show / refund rate | B14: =J9 -> 0.05 | P14: Productive Angel hours | Q14: =Q13*$B$9 -> 960 | U14: Transport payment cost | V14: =$B$16*SUMPRODUCT(I37:I66,'Service Economics'!W5:W34) -> 0 | W14: Case 2 transport collections
A15: Case 1 mix — patient arranges transport | B15: =1-J11 -> 0.6 | P15: Weighted avg service hours | Q15: =S45 -> 4.62 | U15: Transport ops / booking support | V15: =$Q$19*$B$16*'Global Inputs'!$B$18 -> 150.48 | W15: Case 2 journeys
A16: Case 2 mix — NivrāaCare arranges 3P cab | B16: =J11 -> 0.4 | P16: Max journeys by Angel hours | Q16: =IF(Q15=0,0,Q14/Q15) -> 207.79221 | U16: Other service-level variable cost | V16: =SUMPRODUCT(I37:I66,H37:H66) -> 0 | W16: Editable by service
A17: Repeat customer journey mix | B17: =J12 -> 0.2 | P17: Max journeys by daily journey cap | Q17: =$B$6*$B$10*$B$7 -> 216 | U17: NC Credits expected cost | V17: =SUMPRODUCT(I37:I66,'Service Economics'!AG5:AG34) -> 2450.2681 | W17: Expected loyalty redemption cost
A18: New customer journey mix | B18: =1-J12 -> 0.8 | P18: Maximum journeys possible | Q18: =MIN(Q16,Q17) -> 207.79221 | U18: TOTAL VARIABLE COST | V18: =SUM(V6:V17) -> 12250.278 | W18: Should reconcile to Net Revenue − Contribution
A19: Avg journeys / repeat family / month | B19: 2 | P19: Completed journeys (actual) | Q19: =MIN(Q18,Q10) -> 37.62
P20: Unmet demand | Q20: =MAX(Q10-Q19,0) -> 0
A21: Editable Monthly Fixed Costs | P21: Actual Angel utilization | Q21: =IF(Q13=0,0,Q19*Q15/Q13) -> 0.18104625
A22: Fixed Cost | B22: Monthly ₹ | C22: Comment | P22: Capacity surplus / (shortage) hours | Q22: =Q14-Q19*Q15 -> 786.1956
A23: Ops Manager / Care Operations | B23: 45000 | C23: Initial Whitefield operating lead
A24: Customer Support | B24: 10000 | C24: Customer + family support | P24: Revenue & Profitability | Q24: Value | R24: Transport Mix / Contribution | S24: Value
A25: Technology / Cloud / Tools | B25: 8000 | C25: Cloud, monitoring, software | P25: Gross customer service revenue | Q25: =SUM(K37:K66) -> 70007.66 | R25: Case 1 completed journeys | S25: =$Q$19*$B$15 -> 22.572
A26: Marketing | B26: 10000 | C26: Pilot acquisition budget | P26: Transport customer collections | Q26: =SUM(L37:L66) -> 9766.152 | R26: Case 2 completed journeys | S26: =$Q$19*$B$16 -> 15.048
A27: Office / Admin | B27: 10000 | C27: Admin, travel, supplies | P27: Total customer collections | Q27: =Q25+Q26 -> 79773.812 | R27: Case 1 contribution | S27: =$Q$19*$B$15*(S47-S50) -> 32851.636
A28: Legal / CA / Compliance | B28: 4000 | C28: Monthly allocation | P28: Illustrative GST on care service | Q28: =Q25-SUM(Y37:Y66) -> 10679.135 | R28: Case 2 contribution | S28: =$Q$19*$B$16*(S48-S50) -> 23992.763
A29: Fixed Insurance | B29: 5000 | C29: Illustrative fixed component | P29: Illustrative GST on coordination fee | Q29: =SUM(Z37:Z66) -> 0 | R29: Mix check | S29: =$B$15+$B$16 -> 1
A30: Founders / Core Team Salary | B30: 0 | C30: Keep editable for founder discussion | P30: Net operating revenue | Q30: =SUM(M37:M66) -> 69094.677
A31: Miscellaneous | B31: 4000 | C31: Contingency / other fixed costs | P31: Total variable costs | Q31: =Q30-Q32 -> 12250.278
A32: TOTAL FIXED COSTS | B32: =SUM(B23:B31)+'Global Inputs'!$B$30 -> 138000 | C32: Includes payroll Angel salaries from Global Inputs | P32: Monthly contribution before fixed costs | Q32: =SUM(N37:N66) -> 56844.399
A33: Included Angel Payroll (memo) | B33: ='Global Inputs'!$B$30 -> 42000 | C33: Already included in TOTAL FIXED COSTS above | P33: Contribution margin | Q33: =IF(Q30=0,0,Q32/Q30) -> 0.82270301
P34: Contribution / completed journey | Q34: =IF(Q19=0,0,Q32/Q19) -> 1511.0154
A35: Whitefield Service Mix — Editable Demand Mix | N35: Contribution / Angel hour used | P35: Contribution / Angel hour used | Q35: =IF(Q19*Q15=0,0,Q32/(Q19*Q15)) -> 327.05961
A36: Service | B36: Category | C36: Hours | D36: Customer Service Price | E36: Case 1 Contribution/Journey | F36: Case 2 Contribution/Journey | G36: Service Mix % | H36: Other Variable Cost/Journey | I36: Completed Journeys | J36: Required Angel Hours | K36: Gross Service Revenue | L36: Transport Collections | M36: Net Operating Revenue | N36: Monthly Contribution Before Fixed Costs | P36: Monthly fixed costs | Q36: =$B$32 -> 138000 | X36: Transport Helper | Y36: Net Service Rev Helper | Z36: Coord GST Helper
A37: ='Service Economics'!A5 -> Hospital Visit | B37: ='Service Economics'!B5 -> Medical Visit | C37: ='Service Economics'!C5 -> 4 | D37: ='Service Economics'!K5 -> 1395 | E37: ='Service Economics'!R5 -> 1076.8784 | F37: ='Service Economics'!AB5 -> 1215.8784 | G37: 0.23 | H37: 0 | I37: =$Q$19*G37 -> 8.6526 | J37: =I37*C37 -> 34.6104 | K37: =I37*D37 -> 12070.377 | L37: =I37*$B$16*'Service Economics'!V5 -> 2246.215 | M37: =I37*('Service Economics'!L5+$B$16*('Service Economics'!T5+'Service Economics'!U5/(1+'Global Inputs'!$B$17))) -> 12475.348 | N37: =I37*($B$15*E37+$B$16*F37-H37) -> 9798.8825 | P37: Monthly EBITDA / operating profit | Q37: =Q32-Q36 -> -81155.601 | X37: =G37*'Service Economics'!V5 -> 149.27 | Y37: =I37*'Service Economics'!L5 -> 10229.133 | Z37: =I37*$B$16*('Service Economics'!U5-'Service Economics'!U5/(1+'Global Inputs'!$B$17)) -> 0
A38: ='Service Economics'!A6 -> Hospital Visit — Concierge at Hospital | B38: ='Service Economics'!B6 -> Medical Visit | C38: ='Service Economics'!C6 -> 3 | D38: ='Service Economics'!K6 -> 916.6 | E38: ='Service Economics'!R6 -> 688.19866 | F38: ='Service Economics'!AB6 -> 827.19866 | G38: 0.12 | H38: 0 | I38: =$Q$19*G38 -> 4.5144 | J38: =I38*C38 -> 13.5432 | K38: =I38*D38 -> 4137.899 | L38: =I38*$B$16*'Service Economics'!V6 -> 1171.9382 | M38: =I38*('Service Economics'!L6+$B$16*('Service Economics'!T6+'Service Economics'!U6/(1+'Global Inputs'!$B$17))) -> 4678.6323 | N38: =I38*($B$15*E38+$B$16*F38-H38) -> 3357.8047 | P38: Operating margin | Q38: =IF(Q30=0,0,Q37/Q30) -> -1.1745565 | X38: =G38*'Service Economics'!V6 -> 77.88 | Y38: =I38*'Service Economics'!L6 -> 3506.6941 | Z38: =I38*$B$16*('Service Economics'!U6-'Service Economics'!U6/(1+'Global Inputs'!$B$17)) -> 0
A39: ='Service Economics'!A7 -> Clinic Visit | B39: ='Service Economics'!B7 -> Medical Visit | C39: ='Service Economics'!C7 -> 2 | D39: ='Service Economics'!K7 -> 737.2 | E39: ='Service Economics'!R7 -> 542.44376 | F39: ='Service Economics'!AB7 -> 681.44376 | G39: 0.09 | H39: 0 | I39: =$Q$19*G39 -> 3.3858 | J39: =I39*C39 -> 6.7716 | K39: =I39*D39 -> 2496.0118 | L39: =I39*$B$16*'Service Economics'!V7 -> 878.95368 | M39: =I39*('Service Economics'!L7+$B$16*('Service Economics'!T7+'Service Economics'!U7/(1+'Global Inputs'!$B$17))) -> 2994.2179 | N39: =I39*($B$15*E39+$B$16*F39-H39) -> 2024.8566 | P39: Break-even journeys / month | Q39: =IF(S51<=0,0,Q36/S51) -> 91.329314 | X39: =G39*'Service Economics'!V7 -> 58.41 | Y39: =I39*'Service Economics'!L7 -> 2115.2642 | Z39: =I39*$B$16*('Service Economics'!U7-'Service Economics'!U7/(1+'Global Inputs'!$B$17)) -> 0
A40: ='Service Economics'!A8 -> Diagnostic Center Visit | B40: ='Service Economics'!B8 -> Medical Visit | C40: ='Service Economics'!C8 -> 3 | D40: ='Service Economics'!K8 -> 961.45 | E40: ='Service Economics'!R8 -> 724.63739 | F40: ='Service Economics'!AB8 -> 863.63739 | G40: 0.08 | H40: 0 | I40: =$Q$19*G40 -> 3.0096 | J40: =I40*C40 -> 9.0288 | K40: =I40*D40 -> 2893.5799 | L40: =I40*$B$16*'Service Economics'!V8 -> 781.29216 | M40: =I40*('Service Economics'!L8+$B$16*('Service Economics'!T8+'Service Economics'!U8/(1+'Global Inputs'!$B$17))) -> 3233.4785 | N40: =I40*($B$15*E40+$B$16*F40-H40) -> 2348.2024 | P40: Break-even journeys / day | Q40: =IF($B$7=0,0,Q39/$B$7) -> 3.0443105 | X40: =G40*'Service Economics'!V8 -> 51.92 | Y40: =I40*'Service Economics'!L8 -> 2452.1864 | Z40: =I40*$B$16*('Service Economics'!U8-'Service Economics'!U8/(1+'Global Inputs'!$B$17)) -> 0
A41: ='Service Economics'!A9 -> Health Check-up Concierge | B41: ='Service Economics'!B9 -> Medical Visit | C41: ='Service Economics'!C9 -> 5 | D41: ='Service Economics'!K9 -> 1544.5 | E41: ='Service Economics'!R9 -> 1198.3408 | F41: ='Service Economics'!AB9 -> 1337.3408 | G41: 0.05 | H41: 0 | I41: =$Q$19*G41 -> 1.881 | J41: =I41*C41 -> 9.405 | K41: =I41*D41 -> 2905.2045 | L41: =I41*$B$16*'Service Economics'!V9 -> 488.3076 | M41: =I41*('Service Economics'!L9+$B$16*('Service Economics'!T9+'Service Economics'!U9/(1+'Global Inputs'!$B$17))) -> 2950.3453 | N41: =I41*($B$15*E41+$B$16*F41-H41) -> 2358.6627 | P41: Break-even customer collections | Q41: =Q39*S52 -> 193665.27 | X41: =G41*'Service Economics'!V9 -> 32.45 | Y41: =I41*'Service Economics'!L9 -> 2462.0377 | Z41: =I41*$B$16*('Service Economics'!U9-'Service Economics'!U9/(1+'Global Inputs'!$B$17)) -> 0
...

Sheet Profit Maximizer
A1: NivrāaCare — Profit Maximizer & CFO Decision Support | Fully Loaded View
A2: Ranks modeled economics after payroll allocation while preserving recurring potential and operational complexity. Manual-priced overnight / 24h services are excluded from automatic 'highest' insights.
A4: CFO Insights — Dynamic
A5: Highest modeled eligible contribution / journey | B5: =INDEX($A$15:$A$44,MATCH(MAX($AL$15:$AL$44),$AL$15:$AL$44,0)) -> Medical Tourism — Concierge Package (24 HR Basis) | C5: Fully loaded blended contribution | D5: =MAX($AL$15:$AL$44) -> 11772.524
A6: Highest modeled eligible contribution / Angel hour | B6: =INDEX($A$15:$A$44,MATCH(MAX($AM$15:$AM$44),$AM$15:$AM$44,0)) -> Medical Tourism — Concierge Package (24 HR Basis) | C6: ₹ / Angel hour | D6: =MAX($AM$15:$AM$44) -> 488.20518
A7: Highest recurring strategic potential | B7: =INDEX($A$15:$A$44,MATCH(MAX($AJ$15:$AJ$44),$AJ$15:$AJ$44,0)) -> Hospital Visit | C7: Potential score | D7: =MAX($AJ$15:$AJ$44) -> 5
A8: Lowest fully loaded margin service | B8: =INDEX('Service Economics'!$A$5:$A$34,MATCH(MIN('Service Economics'!$AM$5:$AM$34),'Service Economics'!$AM$5:$AM$34,0)) -> Medical Records Concierge | C8: Fully loaded margin | D8: =MIN('Service Economics'!$AM$5:$AM$34) -> 0.40106519
A9: Recommended transport mix | B9: =IF(AVERAGE($G$15:$G$44)>AVERAGE($F$15:$F$44),"Case 2 primary / Case 1 fallback","Case 1 primary") -> Case 2 primary / Case 1 fallback | C9: Current break-even volume | D9: ='Whitefield Monthly Projection'!$Q$39 -> 91.329314
A10: Biggest profit lever | B10: =INDEX($A$51:$A$63,MATCH(MAX($I$51:$I$63),$I$51:$I$63,0)) -> Customer leads / day | C10: Biggest unit-economics risk | D10: =IF('Whitefield Monthly Projection'!$Q$21<'Whitefield Monthly Projection'!$B$9*0.8,"Low Whitefield demand density / Angel under-utilization",IF('Whitefield Monthly Projection'!$S$45>4,"Long hospital waiting / journey duration","Transport/payment leakage")) -> Low Whitefield demand density / Angel under-utilization
A11: ="Model insight: "&B6&" currently has the highest modeled contribution per Angel hour. Commercial priority must also consider repeat potential, operational complexity and manual-pricing status; do not treat the top modeled service as an automatic launch recommendation." -> Model insight: Medical Tourism — Concierge Package (24 HR Basis) currently has the highest modeled contribution per Angel hour. Commercial priority must also consider repeat potential, operational complexity and manual-pricing status; do not treat the top modeled service as an automatic launch recommendation.
A13: Service Profitability & Capacity Ranking — Incremental + Fully Loaded Views
A14: Service | B14: Category | C14: Hours | D14: Customer Price | E14: Revenue / Angel Hr | F14: Case 1 Contribution | G14: Case 2 Contribution | H14: Blended Contribution / Journey | I14: Contribution Margin | J14: Contribution / Angel Hr | K14: Repeat Potential (1-5) | L14: Operational Complexity (1-5) | M14: Transport Dependency (1-5) | N14: Strategic Weight (0.5-1.5) | O14: Capacity Efficiency Score | P14: Model Score | Q14: Recommended Priority | R14: Current Mix % | S14: Optimization Score | T14: Optimized Mix % | U14: Recurring Service? | V14: Rate Multiplier | W14: Fixed Premium | X14: Recurring Profit/Hr | Y14: Price Sensitivity Weight | Z14: Angel Hr Weight | AA14: Min Booking Test Price | AB14: Addl-Hour Test Price | AC14: Current Collection/Journey | AD14: Optimized Collection Weight | AE14: Optimized Contribution Weight | AF14: Optimized Hours Weight | AG14: Case 1 Fully Loaded Contribution | AH14: Case 2 Fully Loaded Contribution | AI14: Fully Loaded Contribution / Angel Hr | AJ14: Recurring / Strategic Potential | AK14: Portfolio | AL14: Auto-Rank Blended Contribution | AM14: Auto-Rank Contribution / Angel Hr
A15: ='Service Economics'!A5 -> Hospital Visit | B15: ='Service Economics'!B5 -> Medical Visit | C15: ='Service Economics'!C5 -> 4 | D15: ='Service Economics'!K5 -> 1395 | E15: =IF(C15=0,0,D15/C15) -> 348.75 | F15: ='Service Economics'!R5 -> 1076.8784 | G15: ='Service Economics'!AB5 -> 1215.8784 | H15: ='Whitefield Monthly Projection'!$B$15*F15+'Whitefield Monthly Projection'!$B$16*G15-'Whitefield Monthly Projection'!H37 -> 1132.4784 | I15: =IF(('Service Economics'!L5+'Whitefield Monthly Projection'!$B$16*'Service Economics'!U5/(1+'Global Inputs'!$B$17))=0,0,H15/('Service Economics'!L5+'Whitefield Monthly Projection'!$B$16*'Service Economics'!U5/(1+'Global Inputs'!$B$17))) -> 0.91196271 | J15: =IF(C15=0,0,H15/C15) -> 283.1196 | K15: 3 | L15: 3 | M15: 5 | N15: 1.2 | O15: =IF(MAX($J$15:$J$44)=0,0,J15/MAX($J$15:$J$44)*100) -> 47.657444 | P15: =(IF(MAX($J$15:$J$44)=0,0,J15/MAX($J$15:$J$44))*0.45+K15/5*0.2+(6-L15)/5*0.15+(6-M15)/5*0.1+N15/1.5*0.1)*100 -> 52.44585 | Q15: =IF(H15<=0,"REVIEW — Economics need improvement",IF(AND(J15>=AVERAGE($J$15:$J$44)*1.15,K15>=4,L15<=3),"CORE — Push aggressively",IF(J15>=AVERAGE($J$15:$J$44),"GROW — Attractive economics",IF(K15>=4,"STRATEGIC — Important but lower margin","REVIEW — Economics need improvement")))) -> REVIEW — Economics need improvement | R15: ='Whitefield Monthly Projection'!G37 -> 0.23 | S15: =MAX(J15,0)^3*(0.5+K15/10)*(0.5+(6-L15)/10)*N15 -> 17428942 | T15: =IF(SUM($S$15:$S$44)=0,R15,0.2*R15+0.8*S15/SUM($S$15:$S$44)) -> 0.066824069 | U15: No | V15: ='Service Economics'!D5 -> 1 | W15: ='Service Economics'!E5 -> 0 | X15: =IF(U15="Yes",J15,0) -> 0 | Y15: =R15*C15*V15 -> 0.92 | Z15: =R15*C15*'Service Economics'!F5 -> 0.92 | AA15: =MAX(C15,$C$53)*'Global Inputs'!$B$5*V15+W15 -> 1196 | AB15: =MAX(C15,'Global Inputs'!$B$22)*'Global Inputs'!$B$5*V15*$C$54+W15 -> 1076.4 | AC15: =D15+'Whitefield Monthly Projection'!$B$16*'Service Economics'!V5 -> 1654.6 | AD15: =T15*AC15 -> 110.5671 | AE15: =T15*H15 -> 75.676814 | AF15: =T15*C15 -> 0.26729628 | AG15: ='Service Economics'!AL5 -> 662.67721 | AH15: ='Service Economics'!AN5 -> 801.67721 | AI15: ='Service Economics'!AP5 -> 165.6693 | AJ15: ='Service Economics'!AQ5 -> 5 | AK15: ='Service Portfolio'!P5 -> SCALE | AL15: =IF(ISNUMBER(SEARCH("Future",'Service Economics'!AH5)),-1000000000,AG15*(1-'Whitefield Monthly Projection'!$B$16)+AH15*'Whitefield Monthly Projection'!$B$16) -> 718.27721 | AM15: =IF(ISNUMBER(SEARCH("Future",'Service Economics'!AH5)),-1000000000,AI15) -> 165.6693
