Workbook

Sheet Global Inputs
A1: NivrāaCare — Global Unit Economics Inputs
A2: Change only blue numbers. Change any input and service profitability updates automatically. NC loyalty assumptions are controlled separately in the 'NC Credits' sheet.
A4: Input | B4: Value | C4: Unit | D4: Source / Note | F4: Governance
A5: Base customer charge per concierge hour | B5: ='MVP1 Pricing & SKU'!$B$7 -> 299 | C5: ₹ / hour | D5: Linked to Global Pricing Config — active master base hourly rate | F5: Founder Assumption
A6: Angel cost per hour | B6: 0 | C6: ₹ / Angel hour | D6: Founder working assumption: ₹700 ÷ 4 hours | E6: When we are keeping 3 Angels on payroll, then we do not have to pay them on per hour basis, so I have made per hour cost as ZERO.Angel payment 14K Per month | F6: Founder Assumption
A7: GST on care service | B7: ='Global Pricing Config'!$B$8 -> 0.18 | C7: % | D7: Illustrative assumption; confirm with CA | F7: Market Test / CA Confirmation
A8: Payment platform fee | B8: 0 | C8: % of customer collection | D8: Editable payment gateway assumption | F8: Market Test
A9: Payment platform fixed fee | B9: 0 | C9: ₹ / transaction | D9: Editable | F9: Founder Assumption
A10: Ops / support allocation | B10: 10 | C10: ₹ / journey | D10: Founder working assumption | F10: Founder Assumption
A11: Insurance / risk reserve | B11: 10 | C11: ₹ / journey | D11: Founder working assumption | F11: Founder Assumption
A12: WhatsApp / SMS / communication | B12: 0.5 | C12: ₹ / journey | D12: Founder working assumption | F12: Founder Assumption
A13: BGV + training allocation | B13: 0 | C13: ₹ / journey | D13: Founder working assumption | F13: Founder Assumption
A14: Refund / service recovery reserve | B14: 36 | C14: ₹ / journey | D14: Founder working assumption | F14: Founder Assumption
A15: Average third-party cab actual | B15: ='Global Pricing Config'!$B$10 -> 500 | C15: ₹ / journey | D15: Founder working assumption for Case 2 | F15: Founder Assumption
A16: Transport coordination fee | B16: ='Global Pricing Config'!$B$9 -> 149 | C16: ₹ / journey | D16: Founder working assumption for Case 2 | F16: Founder Assumption
A17: GST on transport coordination fee | B17: 0 | C17: % | D17: Set to applicable rate after CA confirmation | F17: Market Test / CA Confirmation
A18: Transport ops / booking support | B18: 10 | C18: ₹ / journey | D18: Founder working assumption | F18: Founder Assumption
A19: Legacy extended-hour price (inactive) | B19: ='MVP1 Pricing & SKU'!$B$8 -> 269 | C19: ₹ / hour | D19: Historical assumption only. Not used in current MVP pricing engine. | F19: Founder Assumption
A20: New customer acquisition cost (sensitivity only) | B20: 299 | C20: ₹ / new family | D20: Illustrative founder assumption for repeat-rate sensitivity | F20: Founder Assumption
A21: Base package hours (sensitivity only) | B21: 4 | C21: hours | D21: Used only in additional-hour sensitivity | F21: Founder Assumption
A22: Minimum booking hours (MVP1) | B22: ='Global Pricing Config'!$B$6 -> 2 | C22: hours | D22: Linked to MVP1 Pricing & SKU | F22: Founder Assumption
A24: PAYROLL ANGEL ECONOMICS
A25: Active payroll Angels | B25: 3 | C25: Angels | D25: Founder Assumption | E25: Initial payroll team assumption | F25: =D25 -> Founder Assumption
A26: Monthly salary / Angel | B26: 14000 | C26: ₹ / Angel / month | D26: Founder Assumption | E26: Based on founder working plan | F26: =D26 -> Founder Assumption
A27: Angel working days / month | B27: 26 | C27: days | D27: Founder Assumption | E27: Editable | F27: =D27 -> Founder Assumption
A28: Scheduled hours / Angel / day | B28: 8 | C28: hours | D28: Founder Assumption | E28: Editable | F28: =D28 -> Founder Assumption
A29: Target productive utilization | B29: 0.65 | C29: % | D29: Founder Assumption | E29: Planning utilization target | F29: =D29 -> Founder Assumption
A30: Monthly Angel payroll | B30: =B25*B26 -> 42000 | C30: ₹ / month | D30: Derived Formula | E30: Active payroll Angels × salary / Angel | F30: =D30 -> Derived Formula
A31: Available Angel hours / month | B31: =B25*B27*B28 -> 624 | C31: hours / month | D31: Derived Formula | E31: Angels × days × scheduled hours | F31: =D31 -> Derived Formula
A32: Target productive Angel hours / month | B32: =B31*B29 -> 405.6 | C32: hours / month | D32: Derived Formula | E32: Available hours × target utilization | F32: =D32 -> Derived Formula
A33: Target fully loaded Angel cost / productive hour | B33: =IF(B32=0,0,B30/B32) -> 103.5503 | C33: ₹ / productive hour | D33: Derived Formula | E33: Payroll ÷ target productive hours | F33: =D33 -> Derived Formula
A34: Current productive Angel hours / month | B34: =#REF!*#REF! -> #REF! | C34: hours / month | D34: Derived Formula | E34: Current completed journeys × weighted avg duration | F34: =D34 -> Derived Formula
A35: Current fully loaded Angel cost / productive hour | B35: =IF(B34=0,0,B30/B34) -> #REF! | C35: ₹ / productive hour | D35: Derived Formula | E35: Payroll ÷ current productive hours | F35: =D35 -> Derived Formula

Sheet Service Economics
A1: NivrāaCare — Dynamic Service Unit Economics | Incremental vs Fully Loaded Contribution
A2: Edit BLUE input cells (hours, service multiplier, fixed premium, Angel count, and optional overrides). MVP-1 pricing is controlled from 'MVP1 Pricing & SKU'; expected NC loyalty cost is controlled from 'NC Credits'. Overnight / very-long-duration rows are marked manual.
A4: Service | B4: Category | C4: Hours | D4: Rate Multiplier | E4: Fixed Premium / Fee | F4: No. of Angels | G4: Angel Cost/Hr Override | H4: Cab Cost Override | I4: Coord. Fee Override | J4: Effective Service Rate / Hr | K4: Customer Service Price (Incl GST; ₹299 × multiplier × billable hours + ₹199 fee) | L4: Net Service Revenue | M4: Effective Angel Cost/Hr | N4: Angel Cost | O4: Payment Platform Cost | P4: Other Variable Care Cost | Q4: CASE 1 Variable Delivery Cost | R4: CASE 1 Contribution Before Fixed Costs | S4: CASE 1 Contribution Margin | T4: Effective 3P Cab Cost | U4: Effective Coordination Fee | V4: Customer Transport Charge | W4: Transport Payment Cost | X4: Transport Ops Cost | Y4: Net Transport Coordination Contribution | Z4: CASE 2 Total Customer Outflow | AA4: CASE 2 Total Direct Cash Cost | AB4: CASE 2 Contribution Before Fixed Costs | AC4: CASE 2 Profit Uplift | AD4: CASE 2 Contribution Margin | AE4: Contribution / Service Hour C1 | AF4: Contribution / Service Hour C2 | AG4: Expected NC Loyalty Cost | AH4: Pricing Mode | AI4: Incremental Angel Cost / Hr | AJ4: Target Fully Loaded Angel Cost / Hr | AK4: Target Fully Loaded Angel Cost | AL4: CASE 1 Fully Loaded Contribution | AM4: CASE 1 Fully Loaded Margin | AN4: CASE 2 Fully Loaded Contribution | AO4: CASE 2 Fully Loaded Margin | AP4: Fully Loaded Contribution / Angel Hr | AQ4: Recurring / Strategic Potential | AR4: Multiplier Reason
A5: Hospital Visit | B5: Medical Visit | C5: 4 | D5: 1 | E5: 0 | F5: 1 | J5: ='MVP1 Pricing & SKU'!$B$7*D5 -> 299 | K5: 1395 | L5: =K5/(1+'Global Inputs'!$B$7) -> 1182.2034 | M5: =IF(G5="",'Global Inputs'!$B$6,G5) -> 0 | N5: =C5*F5*M5 -> 0 | O5: =K5*'Global Inputs'!$B$8+'Global Inputs'!$B$9 -> 0 | P5: =SUM('Global Inputs'!$B$10:$B$14) -> 56.5 | Q5: =SUM(N5:P5)+AG5 -> 105.325 | R5: =L5-Q5 -> 1076.8784 | S5: =IF(L5=0,0,R5/L5) -> 0.91090789 | T5: =IF(H5="",'Global Inputs'!$B$15,H5) -> 500 | U5: =IF(I5="",'Global Inputs'!$B$16,I5) -> 149 | V5: =T5+U5 -> 649 | W5: =V5*'Global Inputs'!$B$8 -> 0 | X5: ='Global Inputs'!$B$18 -> 10 | Y5: =U5/(1+'Global Inputs'!$B$17)-W5-X5 -> 139 | Z5: =K5+V5 -> 2044 | AA5: =Q5+T5+W5+X5 -> 615.325 | AB5: =R5+Y5 -> 1215.8784 | AC5: =AB5-R5 -> 139 | AD5: 0.91336786 | AE5: =IF(C5=0,0,R5/C5) -> 269.2196 | AF5: =IF(C5=0,0,AB5/C5) -> 303.9696 | AG5: =L5*'NC Credits'!$B$15 -> 48.825 | AH5: =IF(OR(ISNUMBER(SEARCH("Overnight",A5)),ISNUMBER(SEARCH("Multi-Day",A5)),ISNUMBER(SEARCH("Medical Tourism",A5))),"MANUAL","AUTO") -> AUTO | AI5: =M5 -> 0 | AJ5: ='Global Inputs'!$B$33 -> 103.5503 | AK5: =C5*F5*AJ5 -> 414.20118 | AL5: =R5+N5-AK5 -> 662.67721 | AM5: =IF(L5=0,0,AL5/L5) -> 0.56054416 | AN5: =AB5+N5-AK5 -> 801.67721 | AO5: =IF((L5+U5/(1+'Global Inputs'!$B$17))=0,0,AN5/(L5+U5/(1+'Global Inputs'!$B$17))) -> 0.60221993 | AP5: =IF(C5*F5=0,0,AL5/(C5*F5)) -> 165.6693 | AQ5: 5 | AR5: Full journey: home → facility → return / safe handover
A6: Hospital Visit — Concierge at Hospital | B6: Medical Visit | C6: 3 | D6: 0.8 | E6: 0 | F6: 1 | J6: ='MVP1 Pricing & SKU'!$B$7*D6 -> 239.2 | K6: 916.6 | L6: =K6/(1+'Global Inputs'!$B$7) -> 776.77966 | M6: =IF(G6="",'Global Inputs'!$B$6,G6) -> 0 | N6: =C6*F6*M6 -> 0 | O6: =K6*'Global Inputs'!$B$8+'Global Inputs'!$B$9 -> 0 | P6: =SUM('Global Inputs'!$B$10:$B$14) -> 56.5 | Q6: =SUM(N6:P6)+AG6 -> 88.581 | R6: =L6-Q6 -> 688.19866 | S6: =IF(L6=0,0,R6/L6) -> 0.8859638 | T6: =IF(H6="",'Global Inputs'!$B$15,H6) -> 500 | U6: =IF(I6="",'Global Inputs'!$B$16,I6) -> 149 | V6: =T6+U6 -> 649 | W6: =V6*'Global Inputs'!$B$8 -> 0 | X6: ='Global Inputs'!$B$18 -> 10 | Y6: =U6/(1+'Global Inputs'!$B$17)-W6-X6 -> 139 | Z6: =K6+V6 -> 1565.6 | AA6: =Q6+T6+W6+X6 -> 598.581 | AB6: =R6+Y6 -> 827.19866 | AC6: =AB6-R6 -> 139 | AD6: 0.8935157 | AE6: =IF(C6=0,0,R6/C6) -> 229.39955 | AF6: =IF(C6=0,0,AB6/C6) -> 275.73289 | AG6: =L6*'NC Credits'!$B$15 -> 32.081 | AH6: =IF(OR(ISNUMBER(SEARCH("Overnight",A6)),ISNUMBER(SEARCH("Multi-Day",A6)),ISNUMBER(SEARCH("Medical Tourism",A6))),"MANUAL","AUTO") -> AUTO | AI6: =M6 -> 0 | AJ6: ='Global Inputs'!$B$33 -> 103.5503 | AK6: =C6*F6*AJ6 -> 310.65089 | AL6: =R6+N6-AK6 -> 377.54777 | AM6: =IF(L6=0,0,AL6/L6) -> 0.4860423 | AN6: =AB6+N6-AK6 -> 516.54777 | AO6: =IF((L6+U6/(1+'Global Inputs'!$B$17))=0,0,AN6/(L6+U6/(1+'Global Inputs'!$B$17))) -> 0.55795973 | AP6: =IF(C6*F6=0,0,AL6/(C6*F6)) -> 125.84926 | AQ6: 4 | AR6: Hospital-only support; reduced travel and handover responsibility
A7: Clinic Visit | B7: Medical Visit | C7: 2 | D7: 0.9 | E7: 0 | F7: 1 | J7: ='MVP1 Pricing & SKU'!$B$7*D7 -> 269.1 | K7: 737.2 | L7: =K7/(1+'Global Inputs'!$B$7) -> 624.74576 | M7: =IF(G7="",'Global Inputs'!$B$6,G7) -> 0 | N7: =C7*F7*M7 -> 0 | O7: =K7*'Global Inputs'!$B$8+'Global Inputs'!$B$9 -> 0 | P7: =SUM('Global Inputs'!$B$10:$B$14) -> 56.5 | Q7: =SUM(N7:P7)+AG7 -> 82.302 | R7: =L7-Q7 -> 542.44376 | S7: =IF(L7=0,0,R7/L7) -> 0.86826321 | T7: =IF(H7="",'Global Inputs'!$B$15,H7) -> 500 | U7: =IF(I7="",'Global Inputs'!$B$16,I7) -> 149 | V7: =T7+U7 -> 649 | W7: =V7*'Global Inputs'!$B$8 -> 0 | X7: ='Global Inputs'!$B$18 -> 10 | Y7: =U7/(1+'Global Inputs'!$B$17)-W7-X7 -> 139 | Z7: =K7+V7 -> 1386.2 | AA7: =Q7+T7+W7+X7 -> 592.302 | AB7: =R7+Y7 -> 681.44376 | AC7: =AB7-R7 -> 139 | AD7: 0.88070759 | AE7: =IF(C7=0,0,R7/C7) -> 271.22188 | AF7: =IF(C7=0,0,AB7/C7) -> 340.72188 | AG7: =L7*'NC Credits'!$B$15 -> 25.802 | AH7: =IF(OR(ISNUMBER(SEARCH("Overnight",A7)),ISNUMBER(SEARCH("Multi-Day",A7)),ISNUMBER(SEARCH("Medical Tourism",A7))),"MANUAL","AUTO") -> AUTO | AI7: =M7 -> 0 | AJ7: ='Global Inputs'!$B$33 -> 103.5503 | AK7: =C7*F7*AJ7 -> 207.10059 | AL7: =R7+N7-AK7 -> 335.34317 | AM7: =IF(L7=0,0,AL7/L7) -> 0.53676742 | AN7: =AB7+N7-AK7 -> 474.34317 | AO7: =IF((L7+U7/(1+'Global Inputs'!$B$17))=0,0,AN7/(L7+U7/(1+'Global Inputs'!$B$17))) -> 0.61304784 | AP7: =IF(C7*F7=0,0,AL7/(C7*F7)) -> 167.67159 | AQ7: 4 | AR7: Shorter, lower-complexity outpatient journey
A8: Diagnostic Center Visit | B8: Medical Visit | C8: 3 | D8: 0.85 | E8: 0 | F8: 1 | J8: ='MVP1 Pricing & SKU'!$B$7*D8 -> 254.15 | K8: 961.45 | L8: =K8/(1+'Global Inputs'!$B$7) -> 814.78814 | M8: =IF(G8="",'Global Inputs'!$B$6,G8) -> 0 | N8: =C8*F8*M8 -> 0 | O8: =K8*'Global Inputs'!$B$8+'Global Inputs'!$B$9 -> 0 | P8: =SUM('Global Inputs'!$B$10:$B$14) -> 56.5 | Q8: =SUM(N8:P8)+AG8 -> 90.15075 | R8: =L8-Q8 -> 724.63739 | S8: =IF(L8=0,0,R8/L8) -> 0.88935682 | T8: =IF(H8="",'Global Inputs'!$B$15,H8) -> 500 | U8: =IF(I8="",'Global Inputs'!$B$16,I8) -> 149 | V8: =T8+U8 -> 649 | W8: =V8*'Global Inputs'!$B$8 -> 0 | X8: ='Global Inputs'!$B$18 -> 10 | Y8: =U8/(1+'Global Inputs'!$B$17)-W8-X8 -> 139 | Z8: =K8+V8 -> 1610.45 | AA8: =Q8+T8+W8+X8 -> 600.15075 | AB8: =R8+Y8 -> 863.63739 | AC8: =AB8-R8 -> 139 | AD8: 0.89608634 | AE8: =IF(C8=0,0,R8/C8) -> 241.5458 | AF8: =IF(C8=0,0,AB8/C8) -> 287.87913 | AG8: =L8*'NC Credits'!$B$15 -> 33.65075 | AH8: =IF(OR(ISNUMBER(SEARCH("Overnight",A8)),ISNUMBER(SEARCH("Multi-Day",A8)),ISNUMBER(SEARCH("Medical Tourism",A8))),"MANUAL","AUTO") -> AUTO | AI8: =M8 -> 0 | AJ8: ='Global Inputs'!$B$33 -> 103.5503 | AK8: =C8*F8*AJ8 -> 310.65089 | AL8: =R8+N8-AK8 -> 413.9865 | AM8: =IF(L8=0,0,AL8/L8) -> 0.50809097 | AN8: =AB8+N8-AK8 -> 552.9865 | AO8: =IF((L8+U8/(1+'Global Inputs'!$B$17))=0,0,AN8/(L8+U8/(1+'Global Inputs'!$B$17))) -> 0.57376355 | AP8: =IF(C8*F8=0,0,AL8/(C8*F8)) -> 137.9955 | AQ8: 4 | AR8: Generally simpler navigation / diagnostic-only workflow
A9: Health Check-up Concierge | B9: Medical Visit | C9: 5 | D9: 0.9 | E9: 0 | F9: 1 | J9: ='MVP1 Pricing & SKU'!$B$7*D9 -> 269.1 | K9: 1544.5 | L9: =K9/(1+'Global Inputs'!$B$7) -> 1308.8983 | M9: =IF(G9="",'Global Inputs'!$B$6,G9) -> 0 | N9: =C9*F9*M9 -> 0 | O9: =K9*'Global Inputs'!$B$8+'Global Inputs'!$B$9 -> 0 | P9: =SUM('Global Inputs'!$B$10:$B$14) -> 56.5 | Q9: =SUM(N9:P9)+AG9 -> 110.5575 | R9: =L9-Q9 -> 1198.3408 | S9: =IF(L9=0,0,R9/L9) -> 0.91553393 | T9: =IF(H9="",'Global Inputs'!$B$15,H9) -> 500 | U9: =IF(I9="",'Global Inputs'!$B$16,I9) -> 149 | V9: =T9+U9 -> 649 | W9: =V9*'Global Inputs'!$B$8 -> 0 | X9: ='Global Inputs'!$B$18 -> 10 | Y9: =U9/(1+'Global Inputs'!$B$17)-W9-X9 -> 139 | Z9: =K9+V9 -> 2193.5 | AA9: =Q9+T9+W9+X9 -> 620.5575 | AB9: =R9+Y9 -> 1337.3408 | AC9: =AB9-R9 -> 139 | AD9: 0.91730733 | AE9: =IF(C9=0,0,R9/C9) -> 239.66816 | AF9: =IF(C9=0,0,AB9/C9) -> 267.46816 | AG9: =L9*'NC Credits'!$B$15 -> 54.0575 | AH9: =IF(OR(ISNUMBER(SEARCH("Overnight",A9)),ISNUMBER(SEARCH("Multi-Day",A9)),ISNUMBER(SEARCH("Medical Tourism",A9))),"MANUAL","AUTO") -> AUTO | AI9: =M9 -> 0 | AJ9: ='Global Inputs'!$B$33 -> 103.5503 | AK9: =C9*F9*AJ9 -> 517.75148 | AL9: =R9+N9-AK9 -> 680.58933 | AM9: =IF(L9=0,0,AL9/L9) -> 0.51997113 | AN9: =AB9+N9-AK9 -> 819.58933 | AO9: =IF((L9+U9/(1+'Global Inputs'!$B$17))=0,0,AN9/(L9+U9/(1+'Global Inputs'!$B$17))) -> 0.56217181 | AP9: =IF(C9*F9=0,0,AL9/(C9*F9)) -> 136.11787 | AQ9: 3 | AR9: Structured preventive-care journey; moderate coordination
A10: Hospital Admission Concierge | B10: Hospital Support | C10: 4 | D10: 1.15 | E10: 0 | F10: 1 | J10: ='MVP1 Pricing & SKU'!$B$7*D10 -> 343.85 | K10: 1574.4 | L10: =K10/(1+'Global Inputs'!$B$7) -> 1334.2373 | M10: =IF(G10="",'Global Inputs'!$B$6,G10) -> 0 | N10: =C10*F10*M10 -> 0 | O10: =K10*'Global Inputs'!$B$8+'Global Inputs'!$B$9 -> 0 | P10: =SUM('Global Inputs'!$B$10:$B$14) -> 56.5 | Q10: =SUM(N10:P10)+AG10 -> 111.604 | R10: =L10-Q10 -> 1222.6333 | S10: =IF(L10=0,0,R10/L10) -> 0.91635371 | T10: =IF(H10="",'Global Inputs'!$B$15,H10) -> 500 | U10: =IF(I10="",'Global Inputs'!$B$16,I10) -> 149 | V10: =T10+U10 -> 649 | W10: =V10*'Global Inputs'!$B$8 -> 0 | X10: ='Global Inputs'!$B$18 -> 10 | Y10: =U10/(1+'Global Inputs'!$B$17)-W10-X10 -> 139 | Z10: =K10+V10 -> 2223.4 | AA10: =Q10+T10+W10+X10 -> 621.604 | AB10: =R10+Y10 -> 1361.6333 | AC10: =AB10-R10 -> 139 | AD10: 0.91801447 | AE10: =IF(C10=0,0,R10/C10) -> 305.65832 | AF10: =IF(C10=0,0,AB10/C10) -> 340.40832 | AG10: =L10*'NC Credits'!$B$15 -> 55.104 | AH10: =IF(OR(ISNUMBER(SEARCH("Overnight",A10)),ISNUMBER(SEARCH("Multi-Day",A10)),ISNUMBER(SEARCH("Medical Tourism",A10))),"MANUAL","AUTO") -> AUTO | AI10: =M10 -> 0 | AJ10: ='Global Inputs'!$B$33 -> 103.5503 | AK10: =C10*F10*AJ10 -> 414.20118 | AL10: =R10+N10-AK10 -> 808.4321 | AM10: =IF(L10=0,0,AL10/L10) -> 0.60591329 | AN10: =AB10+N10-AK10 -> 947.4321 | AO10: =IF((L10+U10/(1+'Global Inputs'!$B$17))=0,0,AN10/(L10+U10/(1+'Global Inputs'!$B$17))) -> 0.63875963 | AP10: =IF(C10*F10=0,0,AL10/(C10*F10)) -> 202.10803 | AQ10: 3 | AR10: Higher coordination, documentation and handoff complexity
A11: Hospital Discharge Concierge | B11: Hospital Support | C11: 4 | D11: 1.1 | E11: 0 | F11: 1 | J11: ='MVP1 Pricing & SKU'!$B$7*D11 -> 328.9 | K11: 1514.6 | L11: =K11/(1+'Global Inputs'!$B$7) -> 1283.5593 | M11: =IF(G11="",'Global Inputs'!$B$6,G11) -> 0 | N11: =C11*F11*M11 -> 0 | O11: =K11*'Global Inputs'!$B$8+'Global Inputs'!$B$9 -> 0 | P11: =SUM('Global Inputs'!$B$10:$B$14) -> 56.5 | Q11: =SUM(N11:P11)+AG11 -> 109.511 | R11: =L11-Q11 -> 1174.0483 | S11: =IF(L11=0,0,R11/L11) -> 0.91468178 | T11: =IF(H11="",'Global Inputs'!$B$15,H11) -> 500 | U11: =IF(I11="",'Global Inputs'!$B$16,I11) -> 149 | V11: =T11+U11 -> 649 | W11: =V11*'Global Inputs'!$B$8 -> 0 | X11: ='Global Inputs'!$B$18 -> 10 | Y11: =U11/(1+'Global Inputs'!$B$17)-W11-X11 -> 139 | Z11: =K11+V11 -> 2163.6 | AA11: =Q11+T11+W11+X11 -> 619.511 | AB11: =R11+Y11 -> 1313.0483 | AC11: =AB11-R11 -> 139 | AD11: 0.91657518 | AE11: =IF(C11=0,0,R11/C11) -> 293.51208 | AF11: =IF(C11=0,0,AB11/C11) -> 328.26208 | AG11: =L11*'NC Credits'!$B$15 -> 53.011 | AH11: =IF(OR(ISNUMBER(SEARCH("Overnight",A11)),ISNUMBER(SEARCH("Multi-Day",A11)),ISNUMBER(SEARCH("Medical Tourism",A11))),"MANUAL","AUTO") -> AUTO | AI11: =M11 -> 0 | AJ11: ='Global Inputs'!$B$33 -> 103.5503 | AK11: =C11*F11*AJ11 -> 414.20118 | AL11: =R11+N11-AK11 -> 759.84714 | AM11: =IF(L11=0,0,AL11/L11) -> 0.59198443 | AN11: =AB11+N11-AK11 -> 898.84714 | AO11: =IF((L11+U11/(1+'Global Inputs'!$B$17))=0,0,AN11/(L11+U11/(1+'Global Inputs'!$B$17))) -> 0.62744148 | AP11: =IF(C11*F11=0,0,AL11/(C11*F11)) -> 189.96178 | AQ11: 3 | AR11: Higher coordination and post-discharge handover responsibility
A12: Overnight Hospital Concierge | B12: Hospital Support | C12: 12 | D12: 0.85 | E12: 299 | F12: 1 | J12: ='MVP1 Pricing & SKU'!$B$7*D12 -> 254.15 | K12: 3547.8 | L12: =K12/(1+'Global Inputs'!$B$7) -> 3006.6102 | M12: =IF(G12="",'Global Inputs'!$B$6,G12) -> 0 | N12: =C12*F12*M12 -> 0 | O12: =K12*'Global Inputs'!$B$8+'Global Inputs'!$B$9 -> 0 | P12: =SUM('Global Inputs'!$B$10:$B$14) -> 56.5 | Q12: =SUM(N12:P12)+AG12 -> 180.673 | R12: =L12-Q12 -> 2825.9372 | S12: =IF(L12=0,0,R12/L12) -> 0.93990807 | T12: =IF(H12="",'Global Inputs'!$B$15,H12) -> 500 | U12: =IF(I12="",'Global Inputs'!$B$16,I12) -> 149 | V12: =T12+U12 -> 649 | W12: =V12*'Global Inputs'!$B$8 -> 0 | X12: ='Global Inputs'!$B$18 -> 10 | Y12: =U12/(1+'Global Inputs'!$B$17)-W12-X12 -> 139 | Z12: =K12+V12 -> 4196.8 | AA12: =Q12+T12+W12+X12 -> 690.673 | AB12: =R12+Y12 -> 2964.9372 | AC12: =AB12-R12 -> 139 | AD12: 0.9395765 | AE12: =IF(C12=0,0,R12/C12) -> 235.49476 | AF12: =IF(C12=0,0,AB12/C12) -> 247.0781 | AG12: =L12*'NC Credits'!$B$15 -> 124.173 | AH12: =IF(OR(ISNUMBER(SEARCH("Overnight",A12)),ISNUMBER(SEARCH("Multi-Day",A12)),ISNUMBER(SEARCH("Medical Tourism",A12))),"MANUAL","AUTO") -> MANUAL | AI12: =M12 -> 0 | AJ12: ='Global Inputs'!$B$33 -> 103.5503 | AK12: =C12*F12*AJ12 -> 1242.6036 | AL12: =R12+N12-AK12 -> 1583.3336 | AM12: =IF(L12=0,0,AL12/L12) -> 0.52661753 | AN12: =AB12+N12-AK12 -> 1722.3336 | AO12: =IF((L12+U12/(1+'Global Inputs'!$B$17))=0,0,AN12/(L12+U12/(1+'Global Inputs'!$B$17))) -> 0.5458005 | AP12: =IF(C12*F12=0,0,AL12/(C12*F12)) -> 131.94447 | AQ12: 2 | AR12: Long-duration service; manual pricing should supersede multiplier
A13: Multi-Day Hospital Concierge (per 12h shift) | B13: Hospital Support | C13: 12 | D13: 0.85 | E13: 299 | F13: 1 | J13: ='MVP1 Pricing & SKU'!$B$7*D13 -> 254.15 | K13: 3547.8 | L13: =K13/(1+'Global Inputs'!$B$7) -> 3006.6102 | M13: =IF(G13="",'Global Inputs'!$B$6,G13) -> 0 | N13: =C13*F13*M13 -> 0 | O13: =K13*'Global Inputs'!$B$8+'Global Inputs'!$B$9 -> 0 | P13: =SUM('Global Inputs'!$B$10:$B$14) -> 56.5 | Q13: =SUM(N13:P13)+AG13 -> 180.673 | R13: =L13-Q13 -> 2825.9372 | S13: =IF(L13=0,0,R13/L13) -> 0.93990807 | T13: =IF(H13="",'Global Inputs'!$B$15,H13) -> 500 | U13: =IF(I13="",'Global Inputs'!$B$16,I13) -> 149 | V13: =T13+U13 -> 649 | W13: =V13*'Global Inputs'!$B$8 -> 0 | X13: ='Global Inputs'!$B$18 -> 10 | Y13: =U13/(1+'Global Inputs'!$B$17)-W13-X13 -> 139 | Z13: =K13+V13 -> 4196.8 | AA13: =Q13+T13+W13+X13 -> 690.673 | AB13: =R13+Y13 -> 2964.9372 | AC13: =AB13-R13 -> 139 | AD13: 0.9395765 | AE13: =IF(C13=0,0,R13/C13) -> 235.49476 | AF13: =IF(C13=0,0,AB13/C13) -> 247.0781 | AG13: =L13*'NC Credits'!$B$15 -> 124.173 | AH13: =IF(OR(ISNUMBER(SEARCH("Overnight",A13)),ISNUMBER(SEARCH("Multi-Day",A13)),ISNUMBER(SEARCH("Medical Tourism",A13))),"MANUAL","AUTO") -> MANUAL | AI13: =M13 -> 0 | AJ13: ='Global Inputs'!$B$33 -> 103.5503 | AK13: =C13*F13*AJ13 -> 1242.6036 | AL13: =R13+N13-AK13 -> 1583.3336 | AM13: =IF(L13=0,0,AL13/L13) -> 0.52661753 | AN13: =AB13+N13-AK13 -> 1722.3336 | AO13: =IF((L13+U13/(1+'Global Inputs'!$B$17))=0,0,AN13/(L13+U13/(1+'Global Inputs'!$B$17))) -> 0.5458005 | AP13: =IF(C13*F13=0,0,AL13/(C13*F13)) -> 131.94447 | AQ13: 2 | AR13: Long-duration service; manual shift pricing
A14: Day Surgery / Procedure Concierge | B14: Procedure & Treatment | C14: 6 | D14: 1.2 | E14: 0 | F14: 1 | J14: ='MVP1 Pricing & SKU'!$B$7*D14 -> 358.8 | K14: 2351.8 | L14: =K14/(1+'Global Inputs'!$B$7) -> 1993.0508 | M14: =IF(G14="",'Global Inputs'!$B$6,G14) -> 0 | N14: =C14*F14*M14 -> 0 | O14: =K14*'Global Inputs'!$B$8+'Global Inputs'!$B$9 -> 0 | P14: =SUM('Global Inputs'!$B$10:$B$14) -> 56.5 | Q14: =SUM(N14:P14)+AG14 -> 138.813 | R14: =L14-Q14 -> 1854.2378 | S14: =IF(L14=0,0,R14/L14) -> 0.9303515 | T14: =IF(H14="",'Global Inputs'!$B$15,H14) -> 500 | U14: =IF(I14="",'Global Inputs'!$B$16,I14) -> 149 | V14: =T14+U14 -> 649 | W14: =V14*'Global Inputs'!$B$8 -> 0 | X14: ='Global Inputs'!$B$18 -> 10 | Y14: =U14/(1+'Global Inputs'!$B$17)-W14-X14 -> 139 | Z14: =K14+V14 -> 3000.8 | AA14: =Q14+T14+W14+X14 -> 648.813 | AB14: =R14+Y14 -> 1993.2378 | AC14: =AB14-R14 -> 139 | AD14: 0.93052779 | AE14: =IF(C14=0,0,R14/C14) -> 309.03964 | AF14: =IF(C14=0,0,AB14/C14) -> 332.20631 | AG14: =L14*'NC Credits'!$B$15 -> 82.313 | AH14: =IF(OR(ISNUMBER(SEARCH("Overnight",A14)),ISNUMBER(SEARCH("Multi-Day",A14)),ISNUMBER(SEARCH("Medical Tourism",A14))),"MANUAL","AUTO") -> AUTO | AI14: =M14 -> 0 | AJ14: ='Global Inputs'!$B$33 -> 103.5503 | AK14: =C14*F14*AJ14 -> 621.30178 | AL14: =R14+N14-AK14 -> 1232.9361 | AM14: =IF(L14=0,0,AL14/L14) -> 0.61861747 | AN14: =AB14+N14-AK14 -> 1371.9361 | AO14: =IF((L14+U14/(1+'Global Inputs'!$B$17))=0,0,AN14/(L14+U14/(1+'Global Inputs'!$B$17))) -> 0.64047783 | AP14: =IF(C14*F14=0,0,AL14/(C14*F14)) -> 205.48935 | AQ14: 3 | AR14: Procedure-day complexity and extended coordination
A15: Pre-Surgery Concierge | B15: Procedure & Treatment | C15: 4 | D15: 1.1 | E15: 0 | F15: 1 | J15: ='MVP1 Pricing & SKU'!$B$7*D15 -> 328.9 | K15: 1514.6 | L15: =K15/(1+'Global Inputs'!$B$7) -> 1283.5593 | M15: =IF(G15="",'Global Inputs'!$B$6,G15) -> 0 | N15: =C15*F15*M15 -> 0 | O15: =K15*'Global Inputs'!$B$8+'Global Inputs'!$B$9 -> 0 | P15: =SUM('Global Inputs'!$B$10:$B$14) -> 56.5 | Q15: =SUM(N15:P15)+AG15 -> 109.511 | R15: =L15-Q15 -> 1174.0483 | S15: =IF(L15=0,0,R15/L15) -> 0.91468178 | T15: =IF(H15="",'Global Inputs'!$B$15,H15) -> 500 | U15: =IF(I15="",'Global Inputs'!$B$16,I15) -> 149 | V15: =T15+U15 -> 649 | W15: =V15*'Global Inputs'!$B$8 -> 0 | X15: ='Global Inputs'!$B$18 -> 10 | Y15: =U15/(1+'Global Inputs'!$B$17)-W15-X15 -> 139 | Z15: =K15+V15 -> 2163.6 | AA15: =Q15+T15+W15+X15 -> 619.511 | AB15: =R15+Y15 -> 1313.0483 | AC15: =AB15-R15 -> 139 | AD15: 0.91657518 | AE15: =IF(C15=0,0,R15/C15) -> 293.51208 | AF15: =IF(C15=0,0,AB15/C15) -> 328.26208 | AG15: =L15*'NC Credits'!$B$15 -> 53.011 | AH15: =IF(OR(ISNUMBER(SEARCH("Overnight",A15)),ISNUMBER(SEARCH("Multi-Day",A15)),ISNUMBER(SEARCH("Medical Tourism",A15))),"MANUAL","AUTO") -> AUTO | AI15: =M15 -> 0 | AJ15: ='Global Inputs'!$B$33 -> 103.5503 | AK15: =C15*F15*AJ15 -> 414.20118 | AL15: =R15+N15-AK15 -> 759.84714 | AM15: =IF(L15=0,0,AL15/L15) -> 0.59198443 | AN15: =AB15+N15-AK15 -> 898.84714 | AO15: =IF((L15+U15/(1+'Global Inputs'!$B$17))=0,0,AN15/(L15+U15/(1+'Global Inputs'!$B$17))) -> 0.62744148 | AP15: =IF(C15*F15=0,0,AL15/(C15*F15)) -> 189.96178 | AQ15: 2 | AR15: Preparation, records and multi-party coordination
A16: Post-Surgery Follow-up | B16: Procedure & Treatment | C16: 3 | D16: 1 | E16: 0 | F16: 1 | J16: ='MVP1 Pricing & SKU'!$B$7*D16 -> 299 | K16: 1096 | L16: =K16/(1+'Global Inputs'!$B$7) -> 928.81356 | M16: =IF(G16="",'Global Inputs'!$B$6,G16) -> 0 | N16: =C16*F16*M16 -> 0 | O16: =K16*'Global Inputs'!$B$8+'Global Inputs'!$B$9 -> 0 | P16: =SUM('Global Inputs'!$B$10:$B$14) -> 56.5 | Q16: =SUM(N16:P16)+AG16 -> 94.86 | R16: =L16-Q16 -> 833.95356 | S16: =IF(L16=0,0,R16/L16) -> 0.89786971 | T16: =IF(H16="",'Global Inputs'!$B$15,H16) -> 500 | U16: =IF(I16="",'Global Inputs'!$B$16,I16) -> 149 | V16: =T16+U16 -> 649 | W16: =V16*'Global Inputs'!$B$8 -> 0 | X16: ='Global Inputs'!$B$18 -> 10 | Y16: =U16/(1+'Global Inputs'!$B$17)-W16-X16 -> 139 | Z16: =K16+V16 -> 1745 | AA16: =Q16+T16+W16+X16 -> 604.86 | AB16: =R16+Y16 -> 972.95356 | AC16: =AB16-R16 -> 139 | AD16: 0.90271045 | AE16: =IF(C16=0,0,R16/C16) -> 277.98452 | AF16: =IF(C16=0,0,AB16/C16) -> 324.31785 | AG16: =L16*'NC Credits'!$B$15 -> 38.36 | AH16: =IF(OR(ISNUMBER(SEARCH("Overnight",A16)),ISNUMBER(SEARCH("Multi-Day",A16)),ISNUMBER(SEARCH("Medical Tourism",A16))),"MANUAL","AUTO") -> AUTO | AI16: =M16 -> 0 | AJ16: ='Global Inputs'!$B$33 -> 103.5503 | AK16: =C16*F16*AJ16 -> 310.65089 | AL16: =R16+N16-AK16 -> 523.30267 | AM16: =IF(L16=0,0,AL16/L16) -> 0.56340981 | AN16: =AB16+N16-AK16 -> 662.30267 | AO16: =IF((L16+U16/(1+'Global Inputs'!$B$17))=0,0,AN16/(L16+U16/(1+'Global Inputs'!$B$17))) -> 0.61448723 | AP16: =IF(C16*F16=0,0,AL16/(C16*F16)) -> 174.43422 | AQ16: 3 | AR16: Standard follow-up journey with moderate coordination
... A34: Family Medical Update Concierge | B34: Continuing Care | C34: 3 | D34: 0.65 | E34: 0 | F34: 1 | J34: ='MVP1 Pricing & SKU'!$B$7*D34 -> 194.35 | K34: 782.05 | L34: =K34/(1+'Global Inputs'!$B$7) -> 662.75424 | M34: =IF(G34="",'Global Inputs'!$B$6,G34) -> 0 | N34: =C34*F34*M34 -> 0 | O34: =K34*'Global Inputs'!$B$8+'Global Inputs'!$B$9 -> 0 | P34: =SUM('Global Inputs'!$B$10:$B$14) -> 56.5 | Q34: =SUM(N34:P34)+AG34 -> 83.87175 | R34: =L34-Q34 -> 578.88249 | S34: =IF(L34=0,0,R34/L34) -> 0.8734497 | T34: =IF(H34="",'Global Inputs'!$B$15,H34) -> 500 | U34: =IF(I34="",'Global Inputs'!$B$16,I34) -> 149 | V34: =T34+U34 -> 649 | W34: =V34*'Global Inputs'!$B$8 -> 0 | X34: ='Global Inputs'!$B$18 -> 10 | Y34: =U34/(1+'Global Inputs'!$B$17)-W34-X34 -> 139 | Z34: =K34+V34 -> 1431.05 | AA34: =Q34+T34+W34+X34 -> 593.87175 | AB34: =R34+Y34 -> 717.88249 | AC34: =AB34-R34 -> 139 | AD34: 0.8843594 | AE34: =IF(C34=0,0,R34/C34) -> 192.96083 | AF34: =IF(C34=0,0,AB34/C34) -> 239.29416 | AG34: =L34*'NC Credits'!$B$15 -> 27.37175 | AH34: =IF(OR(ISNUMBER(SEARCH("Overnight",A34)),ISNUMBER(SEARCH("Multi-Day",A34)),ISNUMBER(SEARCH("Medical Tourism",A34))),"MANUAL","AUTO") -> AUTO | AI34: =M34 -> 0 | AJ34: ='Global Inputs'!$B$33 -> 103.5503 | AK34: =C34*F34*AJ34 -> 310.65089 | AL34: =R34+N34-AK34 -> 268.2316 | AM34: =IF(L34=0,0,AL34/L34) -> 0.40472257 | AN34: =AB34+N34-AK34 -> 407.2316 | AO34: =IF((L34+U34/(1+'Global Inputs'!$B$17))=0,0,AN34/(L34+U34/(1+'Global Inputs'!$B$17))) -> 0.50166859 | AP34: =IF(C34*F34=0,0,AL34/(C34*F34)) -> 89.410533 | AQ34: 5 | AR34: Communication-focused support; no full physical journey

Sheet Profit Maximizer
A1: NivrāaCare — Profit Maximizer & CFO Decision Support | Fully Loaded View
A2: Ranks modeled economics after payroll allocation while preserving recurring potential and operational complexity. Manual-priced overnight / 24h services are excluded from automatic 'highest' insights.
A4: CFO Insights — Dynamic
A5: Highest modeled eligible contribution / journey | B5: =INDEX($A$15:$A$44,MATCH(MAX($AL$15:$AL$44),$AL$15:$AL$44,0)) -> #REF! | C5: Fully loaded blended contribution | D5: =MAX($AL$15:$AL$44) -> #REF!
A6: Highest modeled eligible contribution / Angel hour | B6: =INDEX($A$15:$A$44,MATCH(MAX($AM$15:$AM$44),$AM$15:$AM$44,0)) -> Medical Tourism — Concierge Package (24 HR Basis) | C6: ₹ / Angel hour | D6: =MAX($AM$15:$AM$44) -> 488.20518
A7: Highest recurring strategic potential | B7: =INDEX($A$15:$A$44,MATCH(MAX($AJ$15:$AJ$44),$AJ$15:$AJ$44,0)) -> Hospital Visit | C7: Potential score | D7: =MAX($AJ$15:$AJ$44) -> 5
A8: Lowest fully loaded margin service | B8: =INDEX('Service Economics'!$A$5:$A$34,MATCH(MIN('Service Economics'!$AM$5:$AM$34),'Service Economics'!$AM$5:$AM$34,0)) -> Medical Records Concierge | C8: Fully loaded margin | D8: =MIN('Service Economics'!$AM$5:$AM$34) -> 0.40106519
A9: Recommended transport mix | B9: =IF(AVERAGE($G$15:$G$44)>AVERAGE($F$15:$F$44),"Case 2 primary / Case 1 fallback","Case 1 primary") -> Case 2 primary / Case 1 fallback | C9: Current break-even volume | D9: =#REF! -> #REF!
A10: Biggest profit lever | B10: =INDEX($A$51:$A$63,MATCH(MAX($I$51:$I$63),$I$51:$I$63,0)) -> #REF! | C10: Biggest unit-economics risk | D10: =IF(#REF!<#REF!*0.8,"Low Whitefield demand density / Angel under-utilization",IF(#REF!>4,"Long hospital waiting / journey duration","Transport/payment leakage")) -> #REF!
A11: ="Model insight: "&B6&" currently has the highest modeled contribution per Angel hour. Commercial priority must also consider repeat potential, operational complexity and manual-pricing status; do not treat the top modeled service as an automatic launch recommendation." -> Model insight: Medical Tourism — Concierge Package (24 HR Basis) currently has the highest modeled contribution per Angel hour. Commercial priority must also consider repeat potential, operational complexity and manual-pricing status; do not treat the top modeled service as an automatic launch recommendation.
A13: Service Profitability & Capacity Ranking — Incremental + Fully Loaded Views
A14: Service | B14: Category | C14: Hours | D14: Customer Price | E14: Revenue / Angel Hr | F14: Case 1 Contribution | G14: Case 2 Contribution | H14: Blended Contribution / Journey | I14: Contribution Margin | J14: Contribution / Angel Hr | K14: Repeat Potential (1-5) | L14: Operational Complexity (1-5) | M14: Transport Dependency (1-5) | N14: Strategic Weight (0.5-1.5) | O14: Capacity Efficiency Score | P14: Model Score | Q14: Recommended Priority | R14: Current Mix % | S14: Optimization Score | T14: Optimized Mix % | U14: Recurring Service? | V14: Rate Multiplier | W14: Fixed Premium | X14: Recurring Profit/Hr | Y14: Price Sensitivity Weight | Z14: Angel Hr Weight | AA14: Min Booking Test Price | AB14: Addl-Hour Test Price | AC14: Current Collection/Journey | AD14: Optimized Collection Weight | AE14: Optimized Contribution Weight | AF14: Optimized Hours Weight | AG14: Case 1 Fully Loaded Contribution | AH14: Case 2 Fully Loaded Contribution | AI14: Fully Loaded Contribution / Angel Hr | AJ14: Recurring / Strategic Potential | AK14: Portfolio | AL14: Auto-Rank Blended Contribution | AM14: Auto-Rank Contribution / Angel Hr
A15: ='Service Economics'!A5 -> Hospital Visit | B15: ='Service Economics'!B5 -> Medical Visit | C15: ='Service Economics'!C5 -> 4 | D15: ='Service Economics'!K5 -> 1395 | E15: =IF(C15=0,0,D15/C15) -> 348.75 | F15: ='Service Economics'!R5 -> 1076.8784 | G15: ='Service Economics'!AB5 -> 1215.8784 | H15: =#REF!*F15+#REF!*G15-#REF! -> #REF! | I15: =IF(('Service Economics'!L5+#REF!*'Service Economics'!U5/(1+'Global Inputs'!$B$17))=0,0,H15/('Service Economics'!L5+#REF!*'Service Economics'!U5/(1+'Global Inputs'!$B$17))) -> #REF! | J15: =IF(C15=0,0,H15/C15) -> #REF! | K15: 3 | L15: 3 | M15: 5 | N15: 1.2 | O15: =IF(MAX($J$15:$J$44)=0,0,J15/MAX($J$15:$J$44)*100) -> #REF! | P15: =(IF(MAX($J$15:$J$44)=0,0,J15/MAX($J$15:$J$44))*0.45+K15/5*0.2+(6-L15)/5*0.15+(6-M15)/5*0.1+N15/1.5*0.1)*100 -> #REF! | Q15: =IF(H15<=0,"REVIEW — Economics need improvement",IF(AND(J15>=AVERAGE($J$15:$J$44)*1.15,K15>=4,L15<=3),"CORE — Push aggressively",IF(J15>=AVERAGE($J$15:$J$44),"GROW — Attractive economics",IF(K15>=4,"STRATEGIC — Important but lower margin","REVIEW — Economics need improvement")))) -> #REF! | R15: =#REF! -> #REF! | S15: =MAX(J15,0)^3*(0.5+K15/10)*(0.5+(6-L15)/10)*N15 -> #REF! | T15: =IF(SUM($S$15:$S$44)=0,R15,0.2*R15+0.8*S15/SUM($S$15:$S$44)) -> #REF! | U15: No | V15: ='Service Economics'!D5 -> 1 | W15: ='Service Economics'!E5 -> 0 | X15: =IF(U15="Yes",J15,0) -> 0 | Y15: =R15*C15*V15 -> #REF! | Z15: =R15*C15*'Service Economics'!F5 -> #REF! | AA15: =MAX(C15,$C$53)*'Global Inputs'!$B$5*V15+W15 -> 1196 | AB15: =MAX(C15,'Global Inputs'!$B$22)*'Global Inputs'!$B$5*V15*$C$54+W15 -> 1076.4 | AC15: =D15+#REF!*'Service Economics'!V5 -> #REF! | AD15: =T15*AC15 -> #REF! | AE15: =T15*H15 -> #REF! | AF15: =T15*C15 -> #REF! | AG15: ='Service Economics'!AL5 -> 662.67721 | AH15: ='Service Economics'!AN5 -> 801.67721 | AI15: ='Service Economics'!AP5 -> 165.6693 | AJ15: ='Service Economics'!AQ5 -> 5 | AK15: =#REF! -> #REF! | AL15: =IF(ISNUMBER(SEARCH("Future",'Service Economics'!AH5)),-1000000000,AG15*(1-#REF!)+AH15*#REF!) -> #REF! | AM15: =IF(ISNUMBER(SEARCH("Future",'Service Economics'!AH5)),-1000000000,AI15) -> 165.6693
A16: ='Service Economics'!A6 -> Hospital Visit — Concierge at Hospital | B16: ='Service Economics'!B6 -> Medical Visit | C16: ='Service Economics'!C6 -> 3 | D16: ='Service Economics'!K6 -> 916.6 | E16: =IF(C16=0,0,D16/C16) -> 305.53333 | F16: ='Service Economics'!R6 -> 688.19866 | G16: ='Service Economics'!AB6 -> 827.19866 | H16: =#REF!*F16+#REF!*G16-#REF! -> #REF! | I16: =IF(('Service Economics'!L6+#REF!*'Service Economics'!U6/(1+'Global Inputs'!$B$17))=0,0,H16/('Service Economics'!L6+#REF!*'Service Economics'!U6/(1+'Global Inputs'!$B$17))) -> #REF! | J16: =IF(C16=0,0,H16/C16) -> #REF! | K16: 3 | L16: 2 | M16: 4 | N16: 1 | O16: =IF(MAX($J$15:$J$44)=0,0,J16/MAX($J$15:$J$44)*100) -> #REF! | P16: =(IF(MAX($J$15:$J$44)=0,0,J16/MAX($J$15:$J$44))*0.45+K16/5*0.2+(6-L16)/5*0.15+(6-M16)/5*0.1+N16/1.5*0.1)*100 -> #REF! | Q16: =IF(H16<=0,"REVIEW — Economics need improvement",IF(AND(J16>=AVERAGE($J$15:$J$44)*1.15,K16>=4,L16<=3),"CORE — Push aggressively",IF(J16>=AVERAGE($J$15:$J$44),"GROW — Attractive economics",IF(K16>=4,"STRATEGIC — Important but lower margin","REVIEW — Economics need improvement")))) -> #REF! | R16: =#REF! -> #REF! | S16: =MAX(J16,0)^3*(0.5+K16/10)*(0.5+(6-L16)/10)*N16 -> #REF! | T16: =IF(SUM($S$15:$S$44)=0,R16,0.2*R16+0.8*S16/SUM($S$15:$S$44)) -> #REF! | U16: No | V16: ='Service Economics'!D6 -> 0.8 | W16: ='Service Economics'!E6 -> 0 | X16: =IF(U16="Yes",J16,0) -> 0 | Y16: =R16*C16*V16 -> #REF! | Z16: =R16*C16*'Service Economics'!F6 -> #REF! | AA16: =MAX(C16,$C$53)*'Global Inputs'!$B$5*V16+W16 -> 717.6 | AB16: =MAX(C16,'Global Inputs'!$B$22)*'Global Inputs'!$B$5*V16*$C$54+W16 -> 645.84 | AC16: =D16+#REF!*'Service Economics'!V6 -> #REF! | AD16: =T16*AC16 -> #REF! | AE16: =T16*H16 -> #REF! | AF16: =T16*C16 -> #REF! | AG16: ='Service Economics'!AL6 -> 377.54777 | AH16: ='Service Economics'!AN6 -> 516.54777 | AI16: ='Service Economics'!AP6 -> 125.84926 | AJ16: ='Service Economics'!AQ6 -> 4 | AK16: =#REF! -> #REF! | AL16: =IF(ISNUMBER(SEARCH("Future",'Service Economics'!AH6)),-1000000000,AG16*(1-#REF!)+AH16*#REF!) -> #REF! | AM16: =IF(ISNUMBER(SEARCH("Future",'Service Economics'!AH6)),-1000000000,AI16) -> 125.84926
A17: ='Service Economics'!A7 -> Clinic Visit | B17: ='Service Economics'!B7 -> Medical Visit | C17: ='Service Economics'!C7 -> 2 | D17: ='Service Economics'!K7 -> 737.2 | E17: =IF(C17=0,0,D17/C17) -> 368.6 | F17: ='Service Economics'!R7 -> 542.44376 | G17: ='Service Economics'!AB7 -> 681.44376 | H17: =#REF!*F17+#REF!*G17-#REF! -> #REF! | I17: =IF(('Service Economics'!L7+#REF!*'Service Economics'!U7/(1+'Global Inputs'!$B$17))=0,0,H17/('Service Economics'!L7+#REF!*'Service Economics'!U7/(1+'Global Inputs'!$B$17))) -> #REF! | J17: =IF(C17=0,0,H17/C17) -> #REF! | K17: 3 | L17: 2 | M17: 4 | N17: 1 | O17: =IF(MAX($J$15:$J$44)=0,0,J17/MAX($J$15:$J$44)*100) -> #REF! | P17: =(IF(MAX($J$15:$J$44)=0,0,J17/MAX($J$15:$J$44))*0.45+K17/5*0.2+(6-L17)/5*0.15+(6-M17)/5*0.1+N17/1.5*0.1)*100 -> #REF! | Q17: =IF(H17<=0,"REVIEW — Economics need improvement",IF(AND(J17>=AVERAGE($J$15:$J$44)*1.15,K17>=4,L17<=3),"CORE — Push aggressively",IF(J17>=AVERAGE($J$15:$J$44),"GROW — Attractive economics",IF(K17>=4,"STRATEGIC — Important but lower margin","REVIEW — Economics need improvement")))) -> #REF! | R17: =#REF! -> #REF! | S17: =MAX(J17,0)^3*(0.5+K17/10)*(0.5+(6-L17)/10)*N17 -> #REF! | T17: =IF(SUM($S$15:$S$44)=0,R17,0.2*R17+0.8*S17/SUM($S$15:$S$44)) -> #REF! | U17: No | V17: ='Service Economics'!D7 -> 0.9 | W17: ='Service Economics'!E7 -> 0 | X17: =IF(U17="Yes",J17,0) -> 0 | Y17: =R17*C17*V17 -> #REF! | Z17: =R17*C17*'Service Economics'!F7 -> #REF! | AA17: =MAX(C17,$C$53)*'Global Inputs'!$B$5*V17+W17 -> 807.3 | AB17: =MAX(C17,'Global Inputs'!$B$22)*'Global Inputs'!$B$5*V17*$C$54+W17 -> 484.38 | AC17: =D17+#REF!*'Service Economics'!V7 -> #REF! | AD17: =T17*AC17 -> #REF! | AE17: =T17*H17 -> #REF! | AF17: =T17*C17 -> #REF! | AG17: ='Service Economics'!AL7 -> 335.34317 | AH17: ='Service Economics'!AN7 -> 474.34317 | AI17: ='Service Economics'!AP7 -> 167.67159 | AJ17: ='Service Economics'!AQ7 -> 4 | AK17: =#REF! -> #REF! | AL17: =IF(ISNUMBER(SEARCH("Future",'Service Economics'!AH7)),-1000000000,AG17*(1-#REF!)+AH17*#REF!) -> #REF! | AM17: =IF(ISNUMBER(SEARCH("Future",'Service Economics'!AH7)),-1000000000,AI17) -> 167.67159
A18: ='Service Economics'!A8 -> Diagnostic Center Visit | B18: ='Service Economics'!B8 -> Medical Visit | C18: ='Service Economics'!C8 -> 3 | D18: ='Service Economics'!K8 -> 961.45 | E18: =IF(C18=0,0,D18/C18) -> 320.48333 | F18: ='Service Economics'!R8 -> 724.63739 | G18: ='Service Economics'!AB8 -> 863.63739 | H18: =#REF!*F18+#REF!*G18-#REF! -> #REF! | I18: =IF(('Service Economics'!L8+#REF!*'Service Economics'!U8/(1+'Global Inputs'!$B$17))=0,0,H18/('Service Economics'!L8+#REF!*'Service Economics'!U8/(1+'Global Inputs'!$B$17))) -> #REF! | J18: =IF(C18=0,0,H18/C18) -> #REF! | K18: 3 | L18: 2 | M18: 4 | N18: 1 | O18: =IF(MAX($J$15:$J$44)=0,0,J18/MAX($J$15:$J$44)*100) -> #REF! | P18: =(IF(MAX($J$15:$J$44)=0,0,J18/MAX($J$15:$J$44))*0.45+K18/5*0.2+(6-L18)/5*0.15+(6-M18)/5*0.1+N18/1.5*0.1)*100 -> #REF! | Q18: =IF(H18<=0,"REVIEW — Economics need improvement",IF(AND(J18>=AVERAGE($J$15:$J$44)*1.15,K18>=4,L18<=3),"CORE — Push aggressively",IF(J18>=AVERAGE($J$15:$J$44),"GROW — Attractive economics",IF(K18>=4,"STRATEGIC — Important but lower margin","REVIEW — Economics need improvement")))) -> #REF! | R18: =#REF! -> #REF! | S18: =MAX(J18,0)^3*(0.5+K18/10)*(0.5+(6-L18)/10)*N18 -> #REF! | T18: =IF(SUM($S$15:$S$44)=0,R18,0.2*R18+0.8*S18/SUM($S$15:$S$44)) -> #REF! | U18: No | V18: ='Service Economics'!D8 -> 0.85 | W18: ='Service Economics'!E8 -> 0 | X18: =IF(U18="Yes",J18,0) -> 0 | Y18: =R18*C18*V18 -> #REF! | Z18: =R18*C18*'Service Economics'!F8 -> #REF! | AA18: =MAX(C18,$C$53)*'Global Inputs'!$B$5*V18+W18 -> 762.45 | AB18: =MAX(C18,'Global Inputs'!$B$22)*'Global Inputs'!$B$5*V18*$C$54+W18 -> 686.205 | AC18: =D18+#REF!*'Service Economics'!V8 -> #REF! | AD18: =T18*AC18 -> #REF! | AE18: =T18*H18 -> #REF! | AF18: =T18*C18 -> #REF! | AG18: ='Service Economics'!AL8 -> 413.9865 | AH18: ='Service Economics'!AN8 -> 552.9865 | AI18: ='Service Economics'!AP8 -> 137.9955 | AJ18: ='Service Economics'!AQ8 -> 4 | AK18: =#REF! -> #REF! | AL18: =IF(ISNUMBER(SEARCH("Future",'Service Economics'!AH8)),-1000000000,AG18*(1-#REF!)+AH18*#REF!) -> #REF! | AM18: =IF(ISNUMBER(SEARCH("Future",'Service Economics'!AH8)),-1000000000,AI18) -> 137.9955
A19: ='Service Economics'!A9 -> Health Check-up Concierge | B19: ='Service Economics'!B9 -> Medical Visit | C19: ='Service Economics'!C9 -> 5 | D19: ='Service Economics'!K9 -> 1544.5 | E19: =IF(C19=0,0,D19/C19) -> 308.9 | F19: ='Service Economics'!R9 -> 1198.3408 | G19: ='Service Economics'!AB9 -> 1337.3408 | H19: =#REF!*F19+#REF!*G19-#REF! -> #REF! | I19: =IF(('Service Economics'!L9+#REF!*'Service Economics'!U9/(1+'Global Inputs'!$B$17))=0,0,H19/('Service Economics'!L9+#REF!*'Service Economics'!U9/(1+'Global Inputs'!$B$17))) -> #REF! | J19: =IF(C19=0,0,H19/C19) -> #REF! | K19: 2 | L19: 3 | M19: 4 | N19: 0.9 | O19: =IF(MAX($J$15:$J$44)=0,0,J19/MAX($J$15:$J$44)*100) -> #REF! | P19: =(IF(MAX($J$15:$J$44)=0,0,J19/MAX($J$15:$J$44))*0.45+K19/5*0.2+(6-L19)/5*0.15+(6-M19)/5*0.1+N19/1.5*0.1)*100 -> #REF! | Q19: =IF(H19<=0,"REVIEW — Economics need improvement",IF(AND(J19>=AVERAGE($J$15:$J$44)*1.15,K19>=4,L19<=3),"CORE — Push aggressively",IF(J19>=AVERAGE($J$15:$J$44),"GROW — Attractive economics",IF(K19>=4,"STRATEGIC — Important but lower margin","REVIEW — Economics need improvement")))) -> #REF! | R19: =#REF! -> #REF! | S19: =MAX(J19,0)^3*(0.5+K19/10)*(0.5+(6-L19)/10)*N19 -> #REF! | T19: =IF(SUM($S$15:$S$44)=0,R19,0.2*R19+0.8*S19/SUM($S$15:$S$44)) -> #REF! | U19: No | V19: ='Service Economics'!D9 -> 0.9 | W19: ='Service Economics'!E9 -> 0 | X19: =IF(U19="Yes",J19,0) -> 0 | Y19: =R19*C19*V19 -> #REF! | Z19: =R19*C19*'Service Economics'!F9 -> #REF! | AA19: =MAX(C19,$C$53)*'Global Inputs'!$B$5*V19+W19 -> 1345.5 | AB19: =MAX(C19,'Global Inputs'!$B$22)*'Global Inputs'!$B$5*V19*$C$54+W19 -> 1210.95 | AC19: =D19+#REF!*'Service Economics'!V9 -> #REF! | AD19: =T19*AC19 -> #REF! | AE19: =T19*H19 -> #REF! | AF19: =T19*C19 -> #REF! | AG19: ='Service Economics'!AL9 -> 680.58933 | AH19: ='Service Economics'!AN9 -> 819.58933 | AI19: ='Service Economics'!AP9 -> 136.11787 | AJ19: ='Service Economics'!AQ9 -> 3 | AK19: =#REF! -> #REF! | AL19: =IF(ISNUMBER(SEARCH("Future",'Service Economics'!AH9)),-1000000000,AG19*(1-#REF!)+AH19*#REF!) -> #REF! | AM19: =IF(ISNUMBER(SEARCH("Future",'Service Economics'!AH9)),-1000000000,AI19) -> 136.11787
A20: ='Service Economics'!A10 -> Hospital Admission Concierge | B20: ='Service Economics'!B10 -> Hospital Support | C20: ='Service Economics'!C10 -> 4 | D20: ='Service Economics'!K10 -> 1574.4 | E20: =IF(C20=0,0,D20/C20) -> 393.6 | F20: ='Service Economics'!R10 -> 1222.6333 | G20: ='Service Economics'!AB10 -> 1361.6333 | H20: =#REF!*F20+#REF!*G20-#REF! -> #REF! | I20: =IF(('Service Economics'!L10+#REF!*'Service Economics'!U10/(1+'Global Inputs'!$B$17))=0,0,H20/('Service Economics'!L10+#REF!*'Service Economics'!U10/(1+'Global Inputs'!$B$17))) -> #REF! | J20: =IF(C20=0,0,H20/C20) -> #REF! | K20: 2 | L20: 4 | M20: 4 | N20: 1.1 | O20: =IF(MAX($J$15:$J$44)=0,0,J20/MAX($J$15:$J$44)*100) -> #REF! | P20: =(IF(MAX($J$15:$J$44)=0,0,J20/MAX($J$15:$J$44))*0.45+K20/5*0.2+(6-L20)/5*0.15+(6-M20)/5*0.1+N20/1.5*0.1)*100 -> #REF! | Q20: =IF(H20<=0,"REVIEW — Economics need improvement",IF(AND(J20>=AVERAGE($J$15:$J$44)*1.15,K20>=4,L20<=3),"CORE — Push aggressively",IF(J20>=AVERAGE($J$15:$J$44),"GROW — Attractive economics",IF(K20>=4,"STRATEGIC — Important but lower margin","REVIEW — Economics need improvement")))) -> #REF! | R20: =#REF! -> #REF! | S20: =MAX(J20,0)^3*(0.5+K20/10)*(0.5+(6-L20)/10)*N20 -> #REF! | T20: =IF(SUM($S$15:$S$44)=0,R20,0.2*R20+0.8*S20/SUM($S$15:$S$44)) -> #REF! | U20: No | V20: ='Service Economics'!D10 -> 1.15 | W20: ='Service Economics'!E10 -> 0 | X20: =IF(U20="Yes",J20,0) -> 0 | Y20: =R20*C20*V20 -> #REF! | Z20: =R20*C20*'Service Economics'!F10 -> #REF! | AA20: =MAX(C20,$C$53)*'Global Inputs'!$B$5*V20+W20 -> 1375.4 | AB20: =MAX(C20,'Global Inputs'!$B$22)*'Global Inputs'!$B$5*V20*$C$54+W20 -> 1237.86 | AC20: =D20+#REF!*'Service Economics'!V10 -> #REF! | AD20: =T20*AC20 -> #REF! | AE20: =T20*H20 -> #REF! | AF20: =T20*C20 -> #REF! | AG20: ='Service Economics'!AL10 -> 808.4321 | AH20: ='Service Economics'!AN10 -> 947.4321 | AI20: ='Service Economics'!AP10 -> 202.10803 | AJ20: ='Service Economics'!AQ10 -> 3 | AK20: =#REF! -> #REF! | AL20: =IF(ISNUMBER(SEARCH("Future",'Service Economics'!AH10)),-1000000000,AG20*(1-#REF!)+AH20*#REF!) -> #REF! | AM20: =IF(ISNUMBER(SEARCH("Future",'Service Economics'!AH10)),-1000000000,AI20) -> 202.10803
A21: ='Service Economics'!A11 -> Hospital Discharge Concierge | B21: ='Service Economics'!B11 -> Hospital Support | C21: ='Service Economics'!C11 -> 4 | D21: ='Service Economics'!K11 -> 1514.6 | E21: =IF(C21=0,0,D21/C21) -> 378.65 | F21: ='Service Economics'!R11 -> 1174.0483 | G21: ='Service Economics'!AB11 -> 1313.0483 | H21: =#REF!*F21+#REF!*G21-#REF! -> #REF! | I21: =IF(('Service Economics'!L11+#REF!*'Service Economics'!U11/(1+'Global Inputs'!$B$17))=0,0,H21/('Service Economics'!L11+#REF!*'Service Economics'!U11/(1+'Global Inputs'!$B$17))) -> #REF! | J21: =IF(C21=0,0,H21/C21) -> #REF! | K21: 2 | L21: 4 | M21: 4 | N21: 1.1 | O21: =IF(MAX($J$15:$J$44)=0,0,J21/MAX($J$15:$J$44)*100) -> #REF! | P21: =(IF(MAX($J$15:$J$44)=0,0,J21/MAX($J$15:$J$44))*0.45+K21/5*0.2+(6-L21)/5*0.15+(6-M21)/5*0.1+N21/1.5*0.1)*100 -> #REF! | Q21: =IF(H21<=0,"REVIEW — Economics need improvement",IF(AND(J21>=AVERAGE($J$15:$J$44)*1.15,K21>=4,L21<=3),"CORE — Push aggressively",IF(J21>=AVERAGE($J$15:$J$44),"GROW — Attractive economics",IF(K21>=4,"STRATEGIC — Important but lower margin","REVIEW — Economics need improvement")))) -> #REF! | R21: =#REF! -> #REF! | S21: =MAX(J21,0)^3*(0.5+K21/10)*(0.5+(6-L21)/10)*N21 -> #REF! | T21: =IF(SUM($S$15:$S$44)=0,R21,0.2*R21+0.8*S21/SUM($S$15:$S$44)) -> #REF! | U21: No | V21: ='Service Economics'!D11 -> 1.1 | W21: ='Service Economics'!E11 -> 0 | X21: =IF(U21="Yes",J21,0) -> 0 | Y21: =R21*C21*V21 -> #REF! | Z21: =R21*C21*'Service Economics'!F11 -> #REF! | AA21: =MAX(C21,$C$53)*'Global Inputs'!$B$5*V21+W21 -> 1315.6 | AB21: =MAX(C21,'Global Inputs'!$B$22)*'Global Inputs'!$B$5*V21*$C$54+W21 -> 1184.04 | AC21: =D21+#REF!*'Service Economics'!V11 -> #REF! | AD21: =T21*AC21 -> #REF! | AE21: =T21*H21 -> #REF! | AF21: =T21*C21 -> #REF! | AG21: ='Service Economics'!AL11 -> 759.84714 | AH21: ='Service Economics'!AN11 -> 898.84714 | AI21: ='Service Economics'!AP11 -> 189.96178 | AJ21: ='Service Economics'!AQ11 -> 3 | AK21: =#REF! -> #REF! | AL21: =IF(ISNUMBER(SEARCH("Future",'Service Economics'!AH11)),-1000000000,AG21*(1-#REF!)+AH21*#REF!) -> #REF! | AM21: =IF(ISNUMBER(SEARCH("Future",'Service Economics'!AH11)),-1000000000,AI21) -> 189.96178
A22: ='Service Economics'!A12 -> Overnight Hospital Concierge | B22: ='Service Economics'!B12 -> Hospital Support | C22: ='Service Economics'!C12 -> 12 | D22: ='Service Economics'!K12 -> 3547.8 | E22: =IF(C22=0,0,D22/C22) -> 295.65 | F22: ='Service Economics'!R12 -> 2825.9372 | G22: ='Service Economics'!AB12 -> 2964.9372 | H22: =#REF!*F22+#REF!*G22-#REF! -> #REF! | I22: =IF(('Service Economics'!L12+#REF!*'Service Economics'!U12/(1+'Global Inputs'!$B$17))=0,0,H22/('Service Economics'!L12+#REF!*'Service Economics'!U12/(1+'Global Inputs'!$B$17))) -> #REF! | J22: =IF(C22=0,0,H22/C22) -> #REF! | K22: 2 | L22: 4 | M22: 2 | N22: 0.9 | O22: =IF(MAX($J$15:$J$44)=0,0,J22/MAX($J$15:$J$44)*100) -> #REF! | P22: =(IF(MAX($J$15:$J$44)=0,0,J22/MAX($J$15:$J$44))*0.45+K22/5*0.2+(6-L22)/5*0.15+(6-M22)/5*0.1+N22/1.5*0.1)*100 -> #REF! | Q22: =IF(H22<=0,"REVIEW — Economics need improvement",IF(AND(J22>=AVERAGE($J$15:$J$44)*1.15,K22>=4,L22<=3),"CORE — Push aggressively",IF(J22>=AVERAGE($J$15:$J$44),"GROW — Attractive economics",IF(K22>=4,"STRATEGIC — Important but lower margin","REVIEW — Economics need improvement")))) -> #REF! | R22: =#REF! -> #REF! | S22: =MAX(J22,0)^3*(0.5+K22/10)*(0.5+(6-L22)/10)*N22 -> #REF! | T22: =IF(SUM($S$15:$S$44)=0,R22,0.2*R22+0.8*S22/SUM($S$15:$S$44)) -> #REF! | U22: No | V22: ='Service Economics'!D12 -> 0.85 | W22: ='Service Economics'!E12 -> 299 | X22: =IF(U22="Yes",J22,0) -> 0 | Y22: =R22*C22*V22 -> #REF! | Z22: =R22*C22*'Service Economics'!F12 -> #REF! | AA22: =MAX(C22,$C$53)*'Global Inputs'!$B$5*V22+W22 -> 3348.8 | AB22: =MAX(C22,'Global Inputs'!$B$22)*'Global Inputs'!$B$5*V22*$C$54+W22 -> 3043.82 | AC22: =D22+#REF!*'Service Economics'!V12 -> #REF! | AD22: =T22*AC22 -> #REF! | AE22: =T22*H22 -> #REF! | AF22: =T22*C22 -> #REF! | AG22: ='Service Economics'!AL12 -> 1583.3336 | AH22: ='Service Economics'!AN12 -> 1722.3336 | AI22: ='Service Economics'!AP12 -> 131.94447 | AJ22: ='Service Economics'!AQ12 -> 2 | AK22: =#REF! -> #REF! | AL22: =IF(ISNUMBER(SEARCH("Future",'Service Economics'!AH12)),-1000000000,AG22*(1-#REF!)+AH22*#REF!) -> #REF! | AM22: =IF(ISNUMBER(SEARCH("Future",'Service Economics'!AH12)),-1000000000,AI22) -> 131.94447
A23: ='Service Economics'!A13 -> Multi-Day Hospital Concierge (per 12h shift) | B23: ='Service Economics'!B13 -> Hospital Support | C23: ='Service Economics'!C13 -> 12 | D23: ='Service Economics'!K13 -> 3547.8 | E23: =IF(C23=0,0,D23/C23) -> 295.65 | F23: ='Service Economics'!R13 -> 2825.9372 | G23: ='Service Economics'!AB13 -> 2964.9372 | H23: =#REF!*F23+#REF!*G23-#REF! -> #REF! | I23: =IF(('Service Economics'!L13+#REF!*'Service Economics'!U13/(1+'Global Inputs'!$B$17))=0,0,H23/('Service Economics'!L13+#REF!*'Service Economics'!U13/(1+'Global Inputs'!$B$17))) -> #REF! | J23: =IF(C23=0,0,H23/C23) -> #REF! | K23: 3 | L23: 5 | M23: 1 | N23: 0.8 | O23: =IF(MAX($J$15:$J$44)=0,0,J23/MAX($J$15:$J$44)*100) -> #REF! | P23: =(IF(MAX($J$15:$J$44)=0,0,J23/MAX($J$15:$J$44))*0.45+K23/5*0.2+(6-L23)/5*0.15+(6-M23)/5*0.1+N23/1.5*0.1)*100 -> #REF! | Q23: =IF(H23<=0,"REVIEW — Economics need improvement",IF(AND(J23>=AVERAGE($J$15:$J$44)*1.15,K23>=4,L23<=3),"CORE — Push aggressively",IF(J23>=AVERAGE($J$15:$J$44),"GROW — Attractive economics",IF(K23>=4,"STRATEGIC — Important but lower margin","REVIEW — Economics need improvement")))) -> #REF! | R23: =#REF! -> #REF! | S23: =MAX(J23,0)^3*(0.5+K23/10)*(0.5+(6-L23)/10)*N23 -> #REF! | T23: =IF(SUM($S$15:$S$44)=0,R23,0.2*R23+0.8*S23/SUM($S$15:$S$44)) -> #REF! | U23: Yes | V23: ='Service Economics'!D13 -> 0.85 | W23: ='Service Economics'!E13 -> 299 | X23: =IF(U23="Yes",J23,0) -> #REF! | Y23: =R23*C23*V23 -> #REF! | Z23: =R23*C23*'Service Economics'!F13 -> #REF! | AA23: =MAX(C23,$C$53)*'Global Inputs'!$B$5*V23+W23 -> 3348.8 | AB23: =MAX(C23,'Global Inputs'!$B$22)*'Global Inputs'!$B$5*V23*$C$54+W23 -> 3043.82 | AC23: =D23+#REF!*'Service Economics'!V13 -> #REF! | AD23: =T23*AC23 -> #REF! | AE23: =T23*H23 -> #REF! | AF23: =T23*C23 -> #REF! | AG23: ='Service Economics'!AL13 -> 1583.3336 | AH23: ='Service Economics'!AN13 -> 1722.3336 | AI23: ='Service Economics'!AP13 -> 131.94447 | AJ23: ='Service Economics'!AQ13 -> 2 | AK23: =#REF! -> #REF! | AL23: =IF(ISNUMBER(SEARCH("Future",'Service Economics'!AH13)),-1000000000,AG23*(1-#REF!)+AH23*#REF!) -> #REF! | AM23: =IF(ISNUMBER(SEARCH("Future",'Service Economics'!AH13)),-1000000000,AI23) -> 131.94447
A24: ='Service Economics'!A14 -> Day Surgery / Procedure Concierge | B24: ='Service Economics'!B14 -> Procedure & Treatment | C24: ='Service Economics'!C14 -> 6 | D24: ='Service Economics'!K14 -> 2351.8 | E24: =IF(C24=0,0,D24/C24) -> 391.96667 | F24: ='Service Economics'!R14 -> 1854.2378 | G24: ='Service Economics'!AB14 -> 1993.2378 | H24: =#REF!*F24+#REF!*G24-#REF! -> #REF! | I24: =IF(('Service Economics'!L14+#REF!*'Service Economics'!U14/(1+'Global Inputs'!$B$17))=0,0,H24/('Service Economics'!L14+#REF!*'Service Economics'!U14/(1+'Global Inputs'!$B$17))) -> #REF! | J24: =IF(C24=0,0,H24/C24) -> #REF! | K24: 2 | L24: 4 | M24: 4 | N24: 1.1 | O24: =IF(MAX($J$15:$J$44)=0,0,J24/MAX($J$15:$J$44)*100) -> #REF! | P24: =(IF(MAX($J$15:$J$44)=0,0,J24/MAX($J$15:$J$44))*0.45+K24/5*0.2+(6-L24)/5*0.15+(6-M24)/5*0.1+N24/1.5*0.1)*100 -> #REF! | Q24: =IF(H24<=0,"REVIEW — Economics need improvement",IF(AND(J24>=AVERAGE($J$15:$J$44)*1.15,K24>=4,L24<=3),"CORE — Push aggressively",IF(J24>=AVERAGE($J$15:$J$44),"GROW — Attractive economics",IF(K24>=4,"STRATEGIC — Important but lower margin","REVIEW — Economics need improvement")))) -> #REF! | R24: =#REF! -> #REF! | S24: =MAX(J24,0)^3*(0.5+K24/10)*(0.5+(6-L24)/10)*N24 -> #REF! | T24: =IF(SUM($S$15:$S$44)=0,R24,0.2*R24+0.8*S24/SUM($S$15:$S$44)) -> #REF! | U24: No | V24: ='Service Economics'!D14 -> 1.2 | W24: ='Service Economics'!E14 -> 0 | X24: =IF(U24="Yes",J24,0) -> 0 | Y24: =R24*C24*V24 -> #REF! | Z24: =R24*C24*'Service Economics'!F14 -> #REF! | AA24: =MAX(C24,$C$53)*'Global Inputs'!$B$5*V24+W24 -> 2152.8 | AB24: =MAX(C24,'Global Inputs'!$B$22)*'Global Inputs'!$B$5*V24*$C$54+W24 -> 1937.52 | AC24: =D24+#REF!*'Service Economics'!V14 -> #REF! | AD24: =T24*AC24 -> #REF! | AE24: =T24*H24 -> #REF! | AF24: =T24*C24 -> #REF! | AG24: ='Service Economics'!AL14 -> 1232.9361 | AH24: ='Service Economics'!AN14 -> 1371.9361 | AI24: ='Service Economics'!AP14 -> 205.48935 | AJ24: ='Service Economics'!AQ14 -> 3 | AK24: =#REF! -> #REF! | AL24: =IF(ISNUMBER(SEARCH("Future",'Service Economics'!AH14)),-1000000000,AG24*(1-#REF!)+AH24*#REF!) -> #REF! | AM24: =IF(ISNUMBER(SEARCH("Future",'Service Economics'!AH14)),-1000000000,AI24) -> 205.48935
A25: ='Service Economics'!A15 -> Pre-Surgery Concierge | B25: ='Service Economics'!B15 -> Procedure & Treatment | C25: ='Service Economics'!C15 -> 4 | D25: ='Service Economics'!K15 -> 1514.6 | E25: =IF(C25=0,0,D25/C25) -> 378.65 | F25: ='Service Economics'!R15 -> 1174.0483 | G25: ='Service Economics'!AB15 -> 1313.0483 | H25: =#REF!*F25+#REF!*G25-#REF! -> #REF! | I25: =IF(('Service Economics'!L15+#REF!*'Service Economics'!U15/(1+'Global Inputs'!$B$17))=0,0,H25/('Service Economics'!L15+#REF!*'Service Economics'!U15/(1+'Global Inputs'!$B$17))) -> #REF! | J25: =IF(C25=0,0,H25/C25) -> #REF! | K25: 2 | L25: 3 | M25: 4 | N25: 1 | O25: =IF(MAX($J$15:$J$44)=0,0,J25/MAX($J$15:$J$44)*100) -> #REF! | P25: =(IF(MAX($J$15:$J$44)=0,0,J25/MAX($J$15:$J$44))*0.45+K25/5*0.2+(6-L25)/5*0.15+(6-M25)/5*0.1+N25/1.5*0.1)*100 -> #REF! | Q25: =IF(H25<=0,"REVIEW — Economics need improvement",IF(AND(J25>=AVERAGE($J$15:$J$44)*1.15,K25>=4,L25<=3),"CORE — Push aggressively",IF(J25>=AVERAGE($J$15:$J$44),"GROW — Attractive economics",IF(K25>=4,"STRATEGIC — Important but lower margin","REVIEW — Economics need improvement")))) -> #REF! | R25: =#REF! -> #REF! | S25: =MAX(J25,0)^3*(0.5+K25/10)*(0.5+(6-L25)/10)*N25 -> #REF! | T25: =IF(SUM($S$15:$S$44)=0,R25,0.2*R25+0.8*S25/SUM($S$15:$S$44)) -> #REF! | U25: No | V25: ='Service Economics'!D15 -> 1.1 | W25: ='Service Economics'!E15 -> 0 | X25: =IF(U25="Yes",J25,0) -> 0 | Y25: =R25*C25*V25 -> #REF! | Z25: =R25*C25*'Service Economics'!F15 -> #REF! | AA25: =MAX(C25,$C$53)*'Global Inputs'!$B$5*V25+W25 -> 1315.6 | AB25: =MAX(C25,'Global Inputs'!$B$22)*'Global Inputs'!$B$5*V25*$C$54+W25 -> 1184.04 | AC25: =D25+#REF!*'Service Economics'!V15 -> #REF! | AD25: =T25*AC25 -> #REF! | AE25: =T25*H25 -> #REF! | AF25: =T25*C25 -> #REF! | AG25: ='Service Economics'!AL15 -> 759.84714 | AH25: ='Service Economics'!AN15 -> 898.84714 | AI25: ='Service Economics'!AP15 -> 189.96178 | AJ25: ='Service Economics'!AQ15 -> 2 | AK25: =#REF! -> #REF! | AL25: =IF(ISNUMBER(SEARCH("Future",'Service Economics'!AH15)),-1000000000,AG25*(1-#REF!)+AH25*#REF!) -> #REF! | AM25: =IF(ISNUMBER(SEARCH("Future",'Service Economics'!AH15)),-1000000000,AI25) -> 189.96178
A26: ='Service Economics'!A16 -> Post-Surgery Follow-up | B26: ='Service Economics'!B16 -> Procedure & Treatment | C26: ='Service Economics'!C16 -> 3 | D26: ='Service Economics'!K16 -> 1096 | E26: =IF(C26=0,0,D26/C26) -> 365.33333 | F26: ='Service Economics'!R16 -> 833.95356 | G26: ='Service Economics'!AB16 -> 972.95356 | H26: =#REF!*F26+#REF!*G26-#REF! -> #REF! | I26: =IF(('Service Economics'!L16+#REF!*'Service Economics'!U16/(1+'Global Inputs'!$B$17))=0,0,H26/('Service Economics'!L16+#REF!*'Service Economics'!U16/(1+'Global Inputs'!$B$17))) -> #REF! | J26: =IF(C26=0,0,H26/C26) -> #REF! | K26: 3 | L26: 3 | M26: 4 | N26: 1 | O26: =IF(MAX($J$15:$J$44)=0,0,J26/MAX($J$15:$J$44)*100) -> #REF! | P26: =(IF(MAX($J$15:$J$44)=0,0,J26/MAX($J$15:$J$44))*0.45+K26/5*0.2+(6-L26)/5*0.15+(6-M26)/5*0.1+N26/1.5*0.1)*100 -> #REF! | Q26: =IF(H26<=0,"REVIEW — Economics need improvement",IF(AND(J26>=AVERAGE($J$15:$J$44)*1.15,K26>=4,L26<=3),"CORE — Push aggressively",IF(J26>=AVERAGE($J$15:$J$44),"GROW — Attractive economics",IF(K26>=4,"STRATEGIC — Important but lower margin","REVIEW — Economics need improvement")))) -> #REF! | R26: =#REF! -> #REF! | S26: =MAX(J26,0)^3*(0.5+K26/10)*(0.5+(6-L26)/10)*N26 -> #REF! | T26: =IF(SUM($S$15:$S$44)=0,R26,0.2*R26+0.8*S26/SUM($S$15:$S$44)) -> #REF! | U26: Yes | V26: ='Service Economics'!D16 -> 1 | W26: ='Service Economics'!E16 -> 0 | X26: =IF(U26="Yes",J26,0) -> #REF! | Y26: =R26*C26*V26 -> #REF! | Z26: =R26*C26*'Service Economics'!F16 -> #REF! | AA26: =MAX(C26,$C$53)*'Global Inputs'!$B$5*V26+W26 -> 897 | AB26: =MAX(C26,'Global Inputs'!$B$22)*'Global Inputs'!$B$5*V26*$C$54+W26 -> 807.3 | AC26: =D26+#REF!*'Service Economics'!V16 -> #REF! | AD26: =T26*AC26 -> #REF! | AE26: =T26*H26 -> #REF! | AF26: =T26*C26 -> #REF! | AG26: ='Service Economics'!AL16 -> 523.30267 | AH26: ='Service Economics'!AN16 -> 662.30267 | AI26: ='Service Economics'!AP16 -> 174.43422 | AJ26: ='Service Economics'!AQ16 -> 3 | AK26: =#REF! -> #REF! | AL26: =IF(ISNUMBER(SEARCH("Future",'Service Economics'!AH16)),-1000000000,AG26*(1-#REF!)+AH26*#REF!) -> #REF! | AM26: =IF(ISNUMBER(SEARCH("Future",'Service Economics'!AH16)),-1000000000,AI26) -> 174.43422
... A44: ='Service Economics'!A34 -> Family Medical Update Concierge | B44: ='Service Economics'!B34 -> Continuing Care | C44: ='Service Economics'!C34 -> 3 | D44: ='Service Economics'!K34 -> 782.05 | E44: =IF(C44=0,0,D44/C44) -> 260.68333 | F44: ='Service Economics'!R34 -> 578.88249 | G44: ='Service Economics'!AB34 -> 717.88249 | H44: =#REF!*F44+#REF!*G44-#REF! -> #REF! | I44: =IF(('Service Economics'!L34+#REF!*'Service Economics'!U34/(1+'Global Inputs'!$B$17))=0,0,H44/('Service Economics'!L34+#REF!*'Service Economics'!U34/(1+'Global Inputs'!$B$17))) -> #REF! | J44: =IF(C44=0,0,H44/C44) -> #REF! | K44: 5 | L44: 1 | M44: 1 | N44: 1.2 | O44: =IF(MAX($J$15:$J$44)=0,0,J44/MAX($J$15:$J$44)*100) -> #REF! | P44: =(IF(MAX($J$15:$J$44)=0,0,J44/MAX($J$15:$J$44))*0.45+K44/5*0.2+(6-L44)/5*0.15+(6-M44)/5*0.1+N44/1.5*0.1)*100 -> #REF! | Q44: =IF(H44<=0,"REVIEW — Economics need improvement",IF(AND(J44>=AVERAGE($J$15:$J$44)*1.15,K44>=4,L44<=3),"CORE — Push aggressively",IF(J44>=AVERAGE($J$15:$J$44),"GROW — Attractive economics",IF(K44>=4,"STRATEGIC — Important but lower margin","REVIEW — Economics need improvement")))) -> #REF! | R44: =#REF! -> #REF! | S44: =MAX(J44,0)^3*(0.5+K44/10)*(0.5+(6-L44)/10)*N44 -> #REF! | T44: =IF(SUM($S$15:$S$44)=0,R44,0.2*R44+0.8*S44/SUM($S$15:$S$44)) -> #REF! | U44: Yes | V44: ='Service Economics'!D34 -> 0.65 | W44: ='Service Economics'!E34 -> 0 | X44: =IF(U44="Yes",J44,0) -> #REF! | Y44: =R44*C44*V44 -> #REF! | Z44: =R44*C44*'Service Economics'!F34 -> #REF! | AA44: =MAX(C44,$C$53)*'Global Inputs'!$B$5*V44+W44 -> 583.05 | AB44: =MAX(C44,'Global Inputs'!$B$22)*'Global Inputs'!$B$5*V44*$C$54+W44 -> 524.745 | AC44: =D44+#REF!*'Service Economics'!V34 -> #REF! | AD44: =T44*AC44 -> #REF! | AE44: =T44*H44 -> #REF! | AF44: =T44*C44 -> #REF! | AG44: ='Service Economics'!AL34 -> 268.2316 | AH44: ='Service Economics'!AN34 -> 407.2316 | AI44: ='Service Economics'!AP34 -> 89.410533 | AJ44: ='Service Economics'!AQ34 -> 5 | AK44: =#REF! -> #REF! | AL44: =IF(ISNUMBER(SEARCH("Future",'Service Economics'!AH34)),-1000000000,AG44*(1-#REF!)+AH44*#REF!) -> #REF! | AM44: =IF(ISNUMBER(SEARCH("Future",'Service Economics'!AH34)),-1000000000,AI44) -> 89.410533
A49: Profit Optimization Levers — One-Variable Sensitivity (All Else Equal)
A50: Lever | B50: Current Value | C50: Test Value | D50: Monthly Revenue | E50: Contribution | F50: Operating Profit | G50: Profit / Angel | H50: Break-even Journeys | I50: Δ Operating Profit
A51: Base price / hour | B51: ='Global Inputs'!$B$5 -> 299 | C51: 499 | D51: =#REF!+#REF!*(SUM($Y$15:$Y$44)*(C51-B51)) -> #REF! | E51: =#REF!+#REF!*((SUM($Y$15:$Y$44)*(C51-B51))/(1+'Global Inputs'!$B$7)*(1-'NC Credits'!$B$15)-(SUM($Y$15:$Y$44)*(C51-B51))*'Global Inputs'!$B$8) -> #REF! | F51: =#REF!+#REF!*((SUM($Y$15:$Y$44)*(C51-B51))/(1+'Global Inputs'!$B$7)*(1-'NC Credits'!$B$15)-(SUM($Y$15:$Y$44)*(C51-B51))*'Global Inputs'!$B$8) -> #REF! | G51: =IF(#REF!=0,0,F51/#REF!) -> #REF! | H51: =IF(E51/#REF!<=0,0,#REF!/(E51/#REF!)) -> #REF! | I51: =F51-#REF! -> #REF!
